Workbook

Sheet Garde
B8: HCTech SARL
B9: Récupération des vapeurs d'essence en station-service
B11: Business Plan & Dossier de financement — Leasing
B12: Modèle Revenue Share 60 / 40 · Machines financées en leasing · Horizon 7 ans
B14: Points clés
B15: Parc cible (An 7) | C15: ='Synthèse'!C5
B16: Résultat net cumulé (7 ans) | C16: ='Synthèse'!C8
B17: Couverture du loyer / machine | C17: ='Synthèse'!C13
B18: DSCR minimum | C18: ='Synthèse'!C14
B19: Trésorerie minimale | C19: ='Synthèse'!C9
B20: Dette bancaire | C20: =0
B23: Société à Responsabilité Limitée — RNE : 1953633L — 01 av. Hedi Khefacha, 2080 Ariana
B25: Document confidentiel — réservé aux établissements de leasing et partenaires financiers identifiés.
B26: Préparé par Mohamed Ridha Belajouza, consultant et conseiller stratégique.

Sheet Hypothèses
B1: Hypothèses du modèle
B2: Toutes les cellules bleues sont modifiables — le classeur entier se recalcule automatiquement.
B4: PARAMÈTRES MACHINE & LEASING
B5: Taux de change USD / TND | C5: 2.95 | E5: Cours de référence
B6: Prix machine (départ usine) | C6: 18000 | D6: USD | E6: Fournisseur GEKO (Corée)
B7: Frais d'import | C7: 0.025 | D7: % | E7: Droits + transit
B8: Installation | C8: 3500 | D8: DT | E8: Prestataire local
B9: Coût machine tout compris (HT) | C9: =C6*C5*(1+C7)+C8 | D9: DT | E9: Base de l'opération de leasing
B10: Taux de leasing machine | C10: 0.12 | D10: %/an | E10: Marché tunisien (plafond usure 16,28 %)
B11: Durée du leasing machine | C11: 5 | D11: ans | E11: Règle Tunisie : leasing équipement 5 ans
B12: Mensualité leasing / machine | C12: =C9*(C10/12)/(1-(1+C10/12)^(-C11*12)) | D12: DT | E12: Annuité constante
B13: Loyer leasing annuel / machine | C13: =C12*12 | D13: DT/an | E13: Pendant 5 ans, puis 0
B14: Maintenance + internet / machine | C14: 120 | D14: DT/mois | E14: OPEX par machine
B16: REVENUS PAR MACHINE
B17: Volume station cible | C17: 12000 | D17: L/jour | E17: Stations ≥ 12 000 L/j (~60 % du parc)
B18: Taux de récupération | C18: 5 | D18: /1000 | E18: Hypothèse médiane (fourchette 3–7/1000)
B19: Essence récupérée / machine | C19: =C17*C18/1000 | D19: L/jour | E19: volume × taux
B20: Prix de l'essence (An 1) | C20: 2.525 | D20: DT/L | E20: Prix à la pompe
B21: Hausse du prix de l'essence | C21: 0.045 | D21: %/an | E21: CAGR réel 2016–2026
B22: Part HCTECH (revenue share) | C22: 0.6 | D22: % | E22: Partage 60 / 40
B23: Part station | C23: =1-C22 | D23: % | E23: Station : 0 investissement
B25: DÉPLOIEMENT DU PARC
B26: Machines par vague | C26: 14 | D26: mach. | E26: Une vague tous les 6 mois
B27: Intervalle entre vagues | C27: 6 | D27: mois
B28: Mois du 1er déploiement | C28: 3 | D28: mois
B29: Nombre de vagues | C29: 14 | D29: vagues
B30: Horizon du plan | C30: 84 | D30: mois | E30: 7 ans
B31: Parc final | C31: =C26*C29 | D31: mach. | E31: Cible à l'An 7
B33: CHARGES DE STRUCTURE
B34: Nombre de gérants / fondateurs | C34: 2 | D34: pers. | E34: Ali + Lamine
B35: Salaire fondateur (An 1) | C35: 2000 | D35: DT/mois
B36: Croissance salaire fondateur | C36: 0.5 | D36: %/an | E36: Plafonnée
B37: Plafond salaire fondateur | C37: 6000 | D37: DT/mois
B38: Salaire technicien (An 1) | C38: 1200 | D38: DT/mois
B39: Croissance salaire technicien | C39: 0.07 | D39: %/an
B40: Machines par technicien | C40: 48 | D40: mach. | E40: Capacité d'un technicien
B41: Charges patronales | C41: 0.21 | D41: % | E41: CNSS + TFP + FOPROLOS
B42: Loyer bureau (An 1) | C42: 1200 | D42: DT/mois
B43: Croissance loyer bureau | C43: 0.06 | D43: %/an
B44: Frais généraux (An 1) | C44: 2000 | D44: DT/mois | E44: Admin, déplacements, divers
...

Sheet Économie machine
B1: Économie d'une machine
B2: Le cœur du modèle : chaque machine s'autofinance et dégage une marge nette.
B4: INVESTISSEMENT & FINANCEMENT
B5: Coût machine tout compris (HT) | C5: ='Hypothèses'!$C$9
B6: Financement | E6: Leasing 100 % (0 cash mobilisé par HCTECH)
B7: Loyer de leasing / mois | C7: ='Hypothèses'!$C$12
B8: Loyer de leasing / an (pendant 5 ans) | C8: ='Hypothèses'!$C$13
B10: REVENUS (scénario réaliste 5/1000)
B11: Essence récupérée / an | C11: ='Hypothèses'!$C$19*365
B12: Valeur brute récupérée / an | C12: ='Hypothèses'!$C$19*365*'Hypothèses'!$C$20
B13: Part HCTECH (60 %) | C13: ='Hypothèses'!$C$19*365*'Hypothèses'!$C$20*'Hypothèses'!$C$22
B14: Part station (40 %) | C14: ='Hypothèses'!$C$19*365*'Hypothèses'!$C$20*'Hypothèses'!$C$23
B16: MARGE PAR MACHINE
B17: (−) Loyer leasing / an | C17: =-'Hypothèses'!$C$13
B18: (−) Maintenance + internet / an | C18: =-'Hypothèses'!$C$14*12
B19: Marge nette PENDANT le leasing (5 ans) | C19: ='Hypothèses'!$C$19*365*'Hypothèses'!$C$20*'Hypothèses'!$C$22-'Hypothèses'!$C$13-'Hypothèses'!$C$14*12
B20: Marge nette APRÈS payoff (An 6-7, loyer = 0) | C20: ='Hypothèses'!$C$19*365*'Hypothèses'!$C$20*'Hypothèses'!$C$22-'Hypothèses'!$C$14*12
B21: Couverture du loyer par la part HCTECH | C21: ='Hypothèses'!$C$19*365*'Hypothèses'!$C$20*'Hypothèses'!$C$22/'Hypothèses'!$C$13

Sheet État de résultat
B1: État de résultat prévisionnel
B2: Présentation normée (Système Comptable des Entreprises — Tunisie). En DT — recalcul automatique.
C4: An 1 | D4: An 2 | E4: An 3 | F4: An 4 | G4: An 5 | H4: An 6 | I4: An 7 | J4: Total 7 ans
B5: Parc de machines en exploitation (fin d'année) — pour mémoire | C5: ='Calcul'!$D$13 | D5: ='Calcul'!$D$25 | E5: ='Calcul'!$D$37 | F5: ='Calcul'!$D$49 | G5: ='Calcul'!$D$61 | H5: ='Calcul'!$D$73 | I5: ='Calcul'!$D$85
B6: PRODUITS D'EXPLOITATION
B7: Revenus (revenue share — part HCTECH 60 %) | C7: =SUMIF('Calcul'!$B$2:$B$85,1,'Calcul'!$H$2:$H$85) | D7: =SUMIF('Calcul'!$B$2:$B$85,2,'Calcul'!$H$2:$H$85) | E7: =SUMIF('Calcul'!$B$2:$B$85,3,'Calcul'!$H$2:$H$85) | F7: =SUMIF('Calcul'!$B$2:$B$85,4,'Calcul'!$H$2:$H$85) | G7: =SUMIF('Calcul'!$B$2:$B$85,5,'Calcul'!$H$2:$H$85) | H7: =SUMIF('Calcul'!$B$2:$B$85,6,'Calcul'!$H$2:$H$85) | I7: =SUMIF('Calcul'!$B$2:$B$85,7,'Calcul'!$H$2:$H$85) | J7: =SUM(C7:I7)
B8: CHARGES D'EXPLOITATION
B9: Achats & charges externes — maintenance machines | C9: =-SUMIF('Calcul'!$B$2:$B$85,1,'Calcul'!$I$2:$I$85) | D9: =-SUMIF('Calcul'!$B$2:$B$85,2,'Calcul'!$I$2:$I$85) | E9: =-SUMIF('Calcul'!$B$2:$B$85,3,'Calcul'!$I$2:$I$85) | F9: =-SUMIF('Calcul'!$B$2:$B$85,4,'Calcul'!$I$2:$I$85) | G9: =-SUMIF('Calcul'!$B$2:$B$85,5,'Calcul'!$I$2:$I$85) | H9: =-SUMIF('Calcul'!$B$2:$B$85,6,'Calcul'!$I$2:$I$85) | I9: =-SUMIF('Calcul'!$B$2:$B$85,7,'Calcul'!$I$2:$I$85) | J9: =SUM(C9:I9)
B10: Charges de leasing — machines | C10: =-SUMIF('Calcul'!$B$2:$B$85,1,'Calcul'!$J$2:$J$85) | D10: =-SUMIF('Calcul'!$B$2:$B$85,2,'Calcul'!$J$2:$J$85) | E10: =-SUMIF('Calcul'!$B$2:$B$85,3,'Calcul'!$J$2:$J$85) | F10: =-SUMIF('Calcul'!$B$2:$B$85,4,'Calcul'!$J$2:$J$85) | G10: =-SUMIF('Calcul'!$B$2:$B$85,5,'Calcul'!$J$2:$J$85) | H10: =-SUMIF('Calcul'!$B$2:$B$85,6,'Calcul'!$J$2:$J$85) | I10: =-SUMIF('Calcul'!$B$2:$B$85,7,'Calcul'!$J$2:$J$85) | J10: =SUM(C10:I10)
B11: Charges de leasing — véhicule | C11: =-SUMIF('Calcul'!$B$2:$B$85,1,'Calcul'!$Q$2:$Q$85) | D11: =-SUMIF('Calcul'!$B$2:$B$85,2,'Calcul'!$Q$2:$Q$85) | E11: =-SUMIF('Calcul'!$B$2:$B$85,3,'Calcul'!$Q$2:$Q$85) | F11: =-SUMIF('Calcul'!$B$2:$B$85,4,'Calcul'!$Q$2:$Q$85) | G11: =-SUMIF('Calcul'!$B$2:$B$85,5,'Calcul'!$Q$2:$Q$85) | H11: =-SUMIF('Calcul'!$B$2:$B$85,6,'Calcul'!$Q$2:$Q$85) | I11: =-SUMIF('Calcul'!$B$2:$B$85,7,'Calcul'!$Q$2:$Q$85) | J11: =SUM(C11:I11)
B12: Charges de personnel | C12: =-SUMIF('Calcul'!$B$2:$B$85,1,'Calcul'!$N$2:$N$85) | D12: =-SUMIF('Calcul'!$B$2:$B$85,2,'Calcul'!$N$2:$N$85) | E12: =-SUMIF('Calcul'!$B$2:$B$85,3,'Calcul'!$N$2:$N$85) | F12: =-SUMIF('Calcul'!$B$2:$B$85,4,'Calcul'!$N$2:$N$85) | G12: =-SUMIF('Calcul'!$B$2:$B$85,5,'Calcul'!$N$2:$N$85) | H12: =-SUMIF('Calcul'!$B$2:$B$85,6,'Calcul'!$N$2:$N$85) | I12: =-SUMIF('Calcul'!$B$2:$B$85,7,'Calcul'!$N$2:$N$85) | J12: =SUM(C12:I12)
B13: Loyer & charges locatives (bureau) | C13: =-SUMIF('Calcul'!$B$2:$B$85,1,'Calcul'!$O$2:$O$85) | D13: =-SUMIF('Calcul'!$B$2:$B$85,2,'Calcul'!$O$2:$O$85) | E13: =-SUMIF('Calcul'!$B$2:$B$85,3,'Calcul'!$O$2:$O$85) | F13: =-SUMIF('Calcul'!$B$2:$B$85,4,'Calcul'!$O$2:$O$85) | G13: =-SUMIF('Calcul'!$B$2:$B$85,5,'Calcul'!$O$2:$O$85) | H13: =-SUMIF('Calcul'!$B$2:$B$85,6,'Calcul'!$O$2:$O$85) | I13: =-SUMIF('Calcul'!$B$2:$B$85,7,'Calcul'!$O$2:$O$85) | J13: =SUM(C13:I13)
B14: Autres charges d'exploitation | C14: =-SUMIF('Calcul'!$B$2:$B$85,1,'Calcul'!$P$2:$P$85) | D14: =-SUMIF('Calcul'!$B$2:$B$85,2,'Calcul'!$P$2:$P$85) | E14: =-SUMIF('Calcul'!$B$2:$B$85,3,'Calcul'!$P$2:$P$85) | F14: =-SUMIF('Calcul'!$B$2:$B$85,4,'Calcul'!$P$2:$P$85) | G14: =-SUMIF('Calcul'!$B$2:$B$85,5,'Calcul'!$P$2:$P$85) | H14: =-SUMIF('Calcul'!$B$2:$B$85,6,'Calcul'!$P$2:$P$85) | I14: =-SUMIF('Calcul'!$B$2:$B$85,7,'Calcul'!$P$2:$P$85) | J14: =SUM(C14:I14)
B15: Total des charges d'exploitation | C15: =-(SUMIF('Calcul'!$B$2:$B$85,1,'Calcul'!$I$2:$I$85)+SUMIF('Calcul'!$B$2:$B$85,1,'Calcul'!$J$2:$J$85)+SUMIF('Calcul'!$B$2:$B$85,1,'Calcul'!$Q$2:$Q$85)+SUMIF('Calcul'!$B$2:$B$85,1,'Calcul'!$N$2:$N$85)+SUMIF('Calcul'!$B$2:$B$85,1,'Calcul'!$O$2:$O$85)+SUMIF('Calcul'!$B$2:$B$85,1,'Calcul'!$P$2:$P$85)) | D15: =-(SUMIF('Calcul'!$B$2:$B$85,2,'Calcul'!$I$2:$I$85)+SUMIF('Calcul'!$B$2:$B$85,2,'Calcul'!$J$2:$J$85)+SUMIF('Calcul'!$B$2:$B$85,2,'Calcul'!$Q$2:$Q$85)+SUMIF('Calcul'!$B$2:$B$85,2,'Calcul'!$N$2:$N$85)+SUMIF('Calcul'!$B$2:$B$85,2,'Calcul'!$O$2:$O$85)+SUMIF('Calcul'!$B$2:$B$85,2,'Calcul'!$P$2:$P$85)) | E15: =-(SUMIF('Calcul'!$B$2:$B$85,3,'Calcul'!$I$2:$I$85)+SUMIF('Calcul'!$B$2:$B$85,3,'Calcul'!$J$2:$J$85)+SUMIF('Calcul'!$B$2:$B$85,3,'Calcul'!$Q$2:$Q$85)+SUMIF('Calcul'!$B$2:$B$85,3,'Calcul'!$N$2:$N$85)+SUMIF('Calcul'!$B$2:$B$85,3,'Calcul'!$O$2:$O$85)+SUMIF('Calcul'!$B$2:$B$85,3,'Calcul'!$P$2:$P$85)) | F15: =-(SUMIF('Calcul'!$B$2:$B$85,4,'Calcul'!$I$2:$I$85)+SUMIF('Calcul'!$B$2:$B$85,4,'Calcul'!$J$2:$J$85)+SUMIF('Calcul'!$B$2:$B$85,4,'Calcul'!$Q$2:$Q$85)+SUMIF('Calcul'!$B$2:$B$85,4,'Calcul'!$N$2:$N$85)+SUMIF('Calcul'!$B$2:$B$85,4,'Calcul'!$O$2:$O$85)+SUMIF('Calcul'!$B$2:$B$85,4,'Calcul'!$P$2:$P$85)) | G15: =-(SUMIF('Calcul'!$B$2:$B$85,5,'Calcul'!$I$2:$I$85)+SUMIF('Calcul'!$B$2:$B$85,5,'Calcul'!$J$2:$J$85)+SUMIF('Calcul'!$B$2:$B$85,5,'Calcul'!$Q$2:$Q$85)+SUMIF('Calcul'!$B$2:$B$85,5,'Calcul'!$N$2:$N$85)+SUMIF('Calcul'!$B$2:$B$85,5,'Calcul'!$O$2:$O$85)+SUMIF('Calcul'!$B$2:$B$85,5,'Calcul'!$P$2:$P$85)) | H15: =-(SUMIF('Calcul'!$B$2:$B$85,6,'Calcul'!$I$2:$I$85)+SUMIF('Calcul'!$B$2:$B$85,6,'Calcul'!$J$2:$J$85)+SUMIF('Calcul'!$B$2:$B$85,6,'Calcul'!$Q$2:$Q$85)+SUMIF('Calcul'!$B$2:$B$85,6,'Calcul'!$N$2:$N$85)+SUMIF('Calcul'!$B$2:$B$85,6,'Calcul'!$O$2:$O$85)+SUMIF('Calcul'!$B$2:$B$85,6,'Calcul'!$P$2:$P$85)) | I15: =-(SUMIF('Calcul'!$B$2:$B$85,7,'Calcul'!$I$2:$I$85)+SUMIF('Calcul'!$B$2:$B$85,7,'Calcul'!$J$2:$J$85)+SUMIF('Calcul'!$B$2:$B$85,7,'Calcul'!$Q$2:$Q$85)+SUMIF('Calcul'!$B$2:$B$85,7,'Calcul'!$N$2:$N$85)+SUMIF('Calcul'!$B$2:$B$85,7,'Calcul'!$O$2:$O$85)+SUMIF('Calcul'!$B$2:$B$85,7,'Calcul'!$P$2:$P$85)) | J15: =SUM(C15:I15)
B16: RÉSULTAT D'EXPLOITATION (= EBITDA, sans amortissement) | C16: =SUMIF('Calcul'!$B$2:$B$85,1,'Calcul'!$R$2:$R$85) | D16: =SUMIF('Calcul'!$B$2:$B$85,2,'Calcul'!$R$2:$R$85) | E16: =SUMIF('Calcul'!$B$2:$B$85,3,'Calcul'!$R$2:$R$85) | F16: =SUMIF('Calcul'!$B$2:$B$85,4,'Calcul'!$R$2:$R$85) | G16: =SUMIF('Calcul'!$B$2:$B$85,5,'Calcul'!$R$2:$R$85) | H16: =SUMIF('Calcul'!$B$2:$B$85,6,'Calcul'!$R$2:$R$85) | I16: =SUMIF('Calcul'!$B$2:$B$85,7,'Calcul'!$R$2:$R$85) | J16: =SUM(C16:I16)
B17: Charges financières nettes | C17: =0 | D17: =0 | E17: =0 | F17: =0 | G17: =0 | H17: =0 | I17: =0 | J17: =SUM(C17:I17)
B18: Résultat des activités ordinaires avant impôt | C18: =SUMIF('Calcul'!$B$2:$B$85,1,'Calcul'!$R$2:$R$85) | D18: =SUMIF('Calcul'!$B$2:$B$85,2,'Calcul'!$R$2:$R$85) | E18: =SUMIF('Calcul'!$B$2:$B$85,3,'Calcul'!$R$2:$R$85) | F18: =SUMIF('Calcul'!$B$2:$B$85,4,'Calcul'!$R$2:$R$85) | G18: =SUMIF('Calcul'!$B$2:$B$85,5,'Calcul'!$R$2:$R$85) | H18: =SUMIF('Calcul'!$B$2:$B$85,6,'Calcul'!$R$2:$R$85) | I18: =SUMIF('Calcul'!$B$2:$B$85,7,'Calcul'!$R$2:$R$85) | J18: =SUM(C18:I18)
B19: Impôt sur les bénéfices (IS 25 % + CSS 3 %) | C19: =-MAX(0,SUMIF('Calcul'!$B$2:$B$85,1,'Calcul'!$R$2:$R$85))*'Hypothèses'!$C$54 | D19: =-MAX(0,SUMIF('Calcul'!$B$2:$B$85,2,'Calcul'!$R$2:$R$85))*'Hypothèses'!$C$54 | E19: =-MAX(0,SUMIF('Calcul'!$B$2:$B$85,3,'Calcul'!$R$2:$R$85))*'Hypothèses'!$C$54 | F19: =-MAX(0,SUMIF('Calcul'!$B$2:$B$85,4,'Calcul'!$R$2:$R$85))*'Hypothèses'!$C$54 | G19: =-MAX(0,SUMIF('Calcul'!$B$2:$B$85,5,'Calcul'!$R$2:$R$85))*'Hypothèses'!$C$54 | H19: =-MAX(0,SUMIF('Calcul'!$B$2:$B$85,6,'Calcul'!$R$2:$R$85))*'Hypothèses'!$C$54 | I19: =-MAX(0,SUMIF('Calcul'!$B$2:$B$85,7,'Calcul'!$R$2:$R$85))*'Hypothèses'!$C$54 | J19: =SUM(C19:I19)
B20: RÉSULTAT NET DE L'EXERCICE | C20: =(SUMIF('Calcul'!$B$2:$B$85,1,'Calcul'!$R$2:$R$85)-MAX(0,SUMIF('Calcul'!$B$2:$B$85,1,'Calcul'!$R$2:$R$85))*'Hypothèses'!$C$54) | D20: =(SUMIF('Calcul'!$B$2:$B$85,2,'Calcul'!$R$2:$R$85)-MAX(0,SUMIF('Calcul'!$B$2:$B$85,2,'Calcul'!$R$2:$R$85))*'Hypothèses'!$C$54) | E20: =(SUMIF('Calcul'!$B$2:$B$85,3,'Calcul'!$R$2:$R$85)-MAX(0,SUMIF('Calcul'!$B$2:$B$85,3,'Calcul'!$R$2:$R$85))*'Hypothèses'!$C$54) | F20: =(SUMIF('Calcul'!$B$2:$B$85,4,'Calcul'!$R$2:$R$85)-MAX(0,SUMIF('Calcul'!$B$2:$B$85,4,'Calcul'!$R$2:$R$85))*'Hypothèses'!$C$54) | G20: =(SUMIF('Calcul'!$B$2:$B$85,5,'Calcul'!$R$2:$R$85)-MAX(0,SUMIF('Calcul'!$B$2:$B$85,5,'Calcul'!$R$2:$R$85))*'Hypothèses'!$C$54) | H20: =(SUMIF('Calcul'!$B$2:$B$85,6,'Calcul'!$R$2:$R$85)-MAX(0,SUMIF('Calcul'!$B$2:$B$85,6,'Calcul'!$R$2:$R$85))*'Hypothèses'!$C$54) | I20: =(SUMIF('Calcul'!$B$2:$B$85,7,'Calcul'!$R$2:$R$85)-MAX(0,SUMIF('Calcul'!$B$2:$B$85,7,'Calcul'!$R$2:$R$85))*'Hypothèses'!$C$54) | J20: =SUM(C20:I20)
B21: Résultat net cumulé | C21: =(SUMIF('Calcul'!$B$2:$B$85,1,'Calcul'!$R$2:$R$85)-MAX(0,SUMIF('Calcul'!$B$2:$B$85,1,'Calcul'!$R$2:$R$85))*'Hypothèses'!$C$54) | D21: =(SUMIF('Calcul'!$B$2:$B$85,1,'Calcul'!$R$2:$R$85)-MAX(0,SUMIF('Calcul'!$B$2:$B$85,1,'Calcul'!$R$2:$R$85))*'Hypothèses'!$C$54)+(SUMIF('Calcul'!$B$2:$B$85,2,'Calcul'!$R$2:$R$85)-MAX(0,SUMIF('Calcul'!$B$2:$B$85,2,'Calcul'!$R$2:$R$85))*'Hypothèses'!$C$54) | E21: =(SUMIF('Calcul'!$B$2:$B$85,1,'Calcul'!$R$2:$R$85)-MAX(0,SUMIF('Calcul'!$B$2:$B$85,1,'Calcul'!$R$2:$R$85))*'Hypothèses'!$C$54)+(SUMIF('Calcul'!$B$2:$B$85,2,'Calcul'!$R$2:$R$85)-MAX(0,SUMIF('Calcul'!$B$2:$B$85,2,'Calcul'!$R$2:$R$85))*'Hypothèses'!$C$54)+(SUMIF('Calcul'!$B$2:$B$85,3,'Calcul'!$R$2:$R$85)-MAX(0,SUMIF('Calcul'!$B$2:$B$85,3,'Calcul'!$R$2:$R$85))*'Hypothèses'!$C$54) | F21: =(SUMIF('Calcul'!$B$2:$B$85,1,'Calcul'!$R$2:$R$85)-MAX(0,SUMIF('Calcul'!$B$2:$B$85,1,'Calcul'!$R$2:$R$85))*'Hypothèses'!$C$54)+(SUMIF('Calcul'!$B$2:$B$85,2,'Calcul'!$R$2:$R$85)-MAX(0,SUMIF('Calcul'!$B$2:$B$85,2,'Calcul'!$R$2:$R$85))*'Hypothèses'!$C$54)+(SUMIF('Calcul'!$B$2:$B$85,3,'Calcul'!$R$2:$R$85)-MAX(0,SUMIF('Calcul'!$B$2:$B$85,3,'Calcul'!$R$2:$R$85))*'Hypothèses'!$C$54)+(SUMIF('Calcul'!$B$2:$B$85,4,'Calcul'!$R$2:$R$85)-MAX(0,SUMIF('Calcul'!$B$2:$B$85,4,'Calcul'!$R$2:$R$85))*'Hypothèses'!$C$54) | G21: =(SUMIF('Calcul'!$B$2:$B$85,1,'Calcul'!$R$2:$R$85)-MAX(0,SUMIF('Calcul'!$B$2:$B$85,1,'Calcul'!$R$2:$R$85))*'Hypothèses'!$C$54)+(SUMIF('Calcul'!$B$2:$B$85,2,'Calcul'!$R$2:$R$85)-MAX(0,SUMIF('Calcul'!$B$2:$B$85,2,'Calcul'!$R$2:$R$85))*'Hypothèses'!$C$54)+(SUMIF('Calcul'!$B$2:$B$85,3,'Calcul'!$R$2:$R$85)-MAX(0,SUMIF('Calcul'!$B$2:$B$85,3,'Calcul'!$R$2:$R$85))*'Hypothèses'!$C$54)+(SUMIF('Calcul'!$B$2:$B$85,4,'Calcul'!$R$2:$R$85)-MAX(0,SUMIF('Calcul'!$B$2:$B$85,4,'Calcul'!$R$2:$R$85))*'Hypothèses'!$C$54)+(SUMIF('Calcul'!$B$2:$B$85,5,'Calcul'!$R$2:$R$85)-MAX(0,SUMIF('Calcul'!$B$2:$B$85,5,'Calcul'!$R$2:$R$85))*'Hypothèses'!$C$54) | H21: =(SUMIF('Calcul'!$B$2:$B$85,1,'Calcul'!$R$2:$R$85)-MAX(0,SUMIF('Calcul'!$B$2:$B$85,1,'Calcul'!$R$2:$R$85))*'Hypothèses'!$C$54)+(SUMIF('Calcul'!$B$2:$B$85,2,'Calcul'!$R$2:$R$85)-MAX(0,SUMIF('Calcul'!$B$2:$B$85,2,'Calcul'!$R$2:$R$85))*'Hypothèses'!$C$54)+(SUMIF('Calcul'!$B$2:$B$85,3,'Calcul'!$R$2:$R$85)-MAX(0,SUMIF('Calcul'!$B$2:$B$85,3,'Calcul'!$R$2:$R$85))*'Hypothèses'!$C$54)+(SUMIF('Calcul'!$B$2:$B$85,4,'Calcul'!$R$2:$R$85)-MAX(0,SUMIF('Calcul'!$B$2:$B$85,4,'Calcul'!$R$2:$R$85))*'Hypothèses'!$C$54)+(SUMIF('Calcul'!$B$2:$B$85,5,'Calcul'!$R$2:$R$85)-MAX(0,SUMIF('Calcul'!$B$2:$B$85,5,'Calcul'!$R$2:$R$85))*'Hypothèses'!$C$54)+(SUMIF('Calcul'!$B$2:$B$85,6,'Calcul'!$R$2:$R$85)-MAX(0,SUMIF('Calcul'!$B$2:$B$85,6,'Calcul'!$R$2:$R$85))*'Hypothèses'!$C$54) | I21: =(SUMIF('Calcul'!$B$2:$B$85,1,'Calcul'!$R$2:$R$85)-MAX(0,SUMIF('Calcul'!$B$2:$B$85,1,'Calcul'!$R$2:$R$85))*'Hypothèses'!$C$54)+(SUMIF('Calcul'!$B$2:$B$85,2,'Calcul'!$R$2:$R$85)-MAX(0,SUMIF('Calcul'!$B$2:$B$85,2,'Calcul'!$R$2:$R$85))*'Hypothèses'!$C$54)+(SUMIF('Calcul'!$B$2:$B$85,3,'Calcul'!$R$2:$R$85)-MAX(0,SUMIF('Calcul'!$B$2:$B$85,3,'Calcul'!$R$2:$R$85))*'Hypothèses'!$C$54)+(SUMIF('Calcul'!$B$2:$B$85,4,'Calcul'!$R$2:$R$85)-MAX(0,SUMIF('Calcul'!$B$2:$B$85,4,'Calcul'!$R$2:$R$85))*'Hypothèses'!$C$54)+(SUMIF('Calcul'!$B$2:$B$85,5,'Calcul'!$R$2:$R$85)-MAX(0,SUMIF('Calcul'!$B$2:$B$85,5,'Calcul'!$R$2:$R$85))*'Hypothèses'!$C$54)+(SUMIF('Calcul'!$B$2:$B$85,6,'Calcul'!$R$2:$R$85)-MAX(0,SUMIF('Calcul'!$B$2:$B$85,6,'Calcul'!$R$2:$R$85))*'Hypothèses'!$C$54)+(SUMIF('Calcul'!$B$2:$B$85,7,'Calcul'!$R$2:$R$85)-MAX(0,SUMIF('Calcul'!$B$2:$B$85,7,'Calcul'!$R$2:$R$85))*'Hypothèses'!$C$54) | J21: =I21
B23: Aucun amortissement de machine : le financement est porté par le leasing (location). Aucune charge financière bancaire : zéro emprunt.

Sheet Bilan
B1: Bilan prévisionnel
B2: Présentation normée (SCE Tunisie). En DT — machines en leasing = location simple (hors bilan). Équilibré par construction.
C4: An 1 | D4: An 2 | E4: An 3 | F4: An 4 | G4: An 5 | H4: An 6 | I4: An 7
B5: ACTIFS
B6: Actifs non courants (immobilisations) | C6: =0 | D6: =0 | E6: =0 | F6: =0 | G6: =0 | H6: =0 | I6: =0
B7: Actifs courants — trésorerie & équivalents | C7: ='Calcul'!$T$13 | D7: ='Calcul'!$T$25-'Hypothèses'!$C$56*((SUMIF('Calcul'!$B$2:$B$85,1,'Calcul'!$R$2:$R$85)-MAX(0,SUMIF('Calcul'!$B$2:$B$85,1,'Calcul'!$R$2:$R$85))*'Hypothèses'!$C$54)) | E7: ='Calcul'!$T$37-'Hypothèses'!$C$56*((SUMIF('Calcul'!$B$2:$B$85,1,'Calcul'!$R$2:$R$85)-MAX(0,SUMIF('Calcul'!$B$2:$B$85,1,'Calcul'!$R$2:$R$85))*'Hypothèses'!$C$54)+(SUMIF('Calcul'!$B$2:$B$85,2,'Calcul'!$R$2:$R$85)-MAX(0,SUMIF('Calcul'!$B$2:$B$85,2,'Calcul'!$R$2:$R$85))*'Hypothèses'!$C$54)) | F7: ='Calcul'!$T$49-'Hypothèses'!$C$56*((SUMIF('Calcul'!$B$2:$B$85,1,'Calcul'!$R$2:$R$85)-MAX(0,SUMIF('Calcul'!$B$2:$B$85,1,'Calcul'!$R$2:$R$85))*'Hypothèses'!$C$54)+(SUMIF('Calcul'!$B$2:$B$85,2,'Calcul'!$R$2:$R$85)-MAX(0,SUMIF('Calcul'!$B$2:$B$85,2,'Calcul'!$R$2:$R$85))*'Hypothèses'!$C$54)+(SUMIF('Calcul'!$B$2:$B$85,3,'Calcul'!$R$2:$R$85)-MAX(0,SUMIF('Calcul'!$B$2:$B$85,3,'Calcul'!$R$2:$R$85))*'Hypothèses'!$C$54)) | G7: ='Calcul'!$T$61-'Hypothèses'!$C$56*((SUMIF('Calcul'!$B$2:$B$85,1,'Calcul'!$R$2:$R$85)-MAX(0,SUMIF('Calcul'!$B$2:$B$85,1,'Calcul'!$R$2:$R$85))*'Hypothèses'!$C$54)+(SUMIF('Calcul'!$B$2:$B$85,2,'Calcul'!$R$2:$R$85)-MAX(0,SUMIF('Calcul'!$B$2:$B$85,2,'Calcul'!$R$2:$R$85))*'Hypothèses'!$C$54)+(SUMIF('Calcul'!$B$2:$B$85,3,'Calcul'!$R$2:$R$85)-MAX(0,SUMIF('Calcul'!$B$2:$B$85,3,'Calcul'!$R$2:$R$85))*'Hypothèses'!$C$54)+(SUMIF('Calcul'!$B$2:$B$85,4,'Calcul'!$R$2:$R$85)-MAX(0,SUMIF('Calcul'!$B$2:$B$85,4,'Calcul'!$R$2:$R$85))*'Hypothèses'!$C$54)) | H7: ='Calcul'!$T$73-'Hypothèses'!$C$56*((SUMIF('Calcul'!$B$2:$B$85,1,'Calcul'!$R$2:$R$85)-MAX(0,SUMIF('Calcul'!$B$2:$B$85,1,'Calcul'!$R$2:$R$85))*'Hypothèses'!$C$54)+(SUMIF('Calcul'!$B$2:$B$85,2,'Calcul'!$R$2:$R$85)-MAX(0,SUMIF('Calcul'!$B$2:$B$85,2,'Calcul'!$R$2:$R$85))*'Hypothèses'!$C$54)+(SUMIF('Calcul'!$B$2:$B$85,3,'Calcul'!$R$2:$R$85)-MAX(0,SUMIF('Calcul'!$B$2:$B$85,3,'Calcul'!$R$2:$R$85))*'Hypothèses'!$C$54)+(SUMIF('Calcul'!$B$2:$B$85,4,'Calcul'!$R$2:$R$85)-MAX(0,SUMIF('Calcul'!$B$2:$B$85,4,'Calcul'!$R$2:$R$85))*'Hypothèses'!$C$54)+(SUMIF('Calcul'!$B$2:$B$85,5,'Calcul'!$R$2:$R$85)-MAX(0,SUMIF('Calcul'!$B$2:$B$85,5,'Calcul'!$R$2:$R$85))*'Hypothèses'!$C$54)) | I7: ='Calcul'!$T$85-'Hypothèses'!$C$56*((SUMIF('Calcul'!$B$2:$B$85,1,'Calcul'!$R$2:$R$85)-MAX(0,SUMIF('Calcul'!$B$2:$B$85,1,'Calcul'!$R$2:$R$85))*'Hypothèses'!$C$54)+(SUMIF('Calcul'!$B$2:$B$85,2,'Calcul'!$R$2:$R$85)-MAX(0,SUMIF('Calcul'!$B$2:$B$85,2,'Calcul'!$R$2:$R$85))*'Hypothèses'!$C$54)+(SUMIF('Calcul'!$B$2:$B$85,3,'Calcul'!$R$2:$R$85)-MAX(0,SUMIF('Calcul'!$B$2:$B$85,3,'Calcul'!$R$2:$R$85))*'Hypothèses'!$C$54)+(SUMIF('Calcul'!$B$2:$B$85,4,'Calcul'!$R$2:$R$85)-MAX(0,SUMIF('Calcul'!$B$2:$B$85,4,'Calcul'!$R$2:$R$85))*'Hypothèses'!$C$54)+(SUMIF('Calcul'!$B$2:$B$85,5,'Calcul'!$R$2:$R$85)-MAX(0,SUMIF('Calcul'!$B$2:$B$85,5,'Calcul'!$R$2:$R$85))*'Hypothèses'!$C$54)+(SUMIF('Calcul'!$B$2:$B$85,6,'Calcul'!$R$2:$R$85)-MAX(0,SUMIF('Calcul'!$B$2:$B$85,6,'Calcul'!$R$2:$R$85))*'Hypothèses'!$C$54))
B8: TOTAL DES ACTIFS | C8: =C6+C7 | D8: =D6+D7 | E8: =E6+E7 | F8: =F6+F7 | G8: =G6+G7 | H8: =H6+H7 | I8: =I6+I7
B9: CAPITAUX PROPRES & PASSIFS
B10: Capital social | C10: ='Hypothèses'!$C$55 | D10: ='Hypothèses'!$C$55 | E10: ='Hypothèses'!$C$55 | F10: ='Hypothèses'!$C$55 | G10: ='Hypothèses'!$C$55 | H10: ='Hypothèses'!$C$55 | I10: ='Hypothèses'!$C$55
B11: Réserves & résultats reportés | C11: =(1-'Hypothèses'!$C$56)*((SUMIF('Calcul'!$B$2:$B$85,1,'Calcul'!$R$2:$R$85)-MAX(0,SUMIF('Calcul'!$B$2:$B$85,1,'Calcul'!$R$2:$R$85))*'Hypothèses'!$C$54)) | D11: =(1-'Hypothèses'!$C$56)*((SUMIF('Calcul'!$B$2:$B$85,1,'Calcul'!$R$2:$R$85)-MAX(0,SUMIF('Calcul'!$B$2:$B$85,1,'Calcul'!$R$2:$R$85))*'Hypothèses'!$C$54)+(SUMIF('Calcul'!$B$2:$B$85,2,'Calcul'!$R$2:$R$85)-MAX(0,SUMIF('Calcul'!$B$2:$B$85,2,'Calcul'!$R$2:$R$85))*'Hypothèses'!$C$54)) | E11: =(1-'Hypothèses'!$C$56)*((SUMIF('Calcul'!$B$2:$B$85,1,'Calcul'!$R$2:$R$85)-MAX(0,SUMIF('Calcul'!$B$2:$B$85,1,'Calcul'!$R$2:$R$85))*'Hypothèses'!$C$54)+(SUMIF('Calcul'!$B$2:$B$85,2,'Calcul'!$R$2:$R$85)-MAX(0,SUMIF('Calcul'!$B$2:$B$85,2,'Calcul'!$R$2:$R$85))*'Hypothèses'!$C$54)+(SUMIF('Calcul'!$B$2:$B$85,3,'Calcul'!$R$2:$R$85)-MAX(0,SUMIF('Calcul'!$B$2:$B$85,3,'Calcul'!$R$2:$R$85))*'Hypothèses'!$C$54)) | F11: =(1-'Hypothèses'!$C$56)*((SUMIF('Calcul'!$B$2:$B$85,1,'Calcul'!$R$2:$R$85)-MAX(0,SUMIF('Calcul'!$B$2:$B$85,1,'Calcul'!$R$2:$R$85))*'Hypothèses'!$C$54)+(SUMIF('Calcul'!$B$2:$B$85,2,'Calcul'!$R$2:$R$85)-MAX(0,SUMIF('Calcul'!$B$2:$B$85,2,'Calcul'!$R$2:$R$85))*'Hypothèses'!$C$54)+(SUMIF('Calcul'!$B$2:$B$85,3,'Calcul'!$R$2:$R$85)-MAX(0,SUMIF('Calcul'!$B$2:$B$85,3,'Calcul'!$R$2:$R$85))*'Hypothèses'!$C$54)+(SUMIF('Calcul'!$B$2:$B$85,4,'Calcul'!$R$2:$R$85)-MAX(0,SUMIF('Calcul'!$B$2:$B$85,4,'Calcul'!$R$2:$R$85))*'Hypothèses'!$C$54)) | G11: =(1-'Hypothèses'!$C$56)*((SUMIF('Calcul'!$B$2:$B$85,1,'Calcul'!$R$2:$R$85)-MAX(0,SUMIF('Calcul'!$B$2:$B$85,1,'Calcul'!$R$2:$R$85))*'Hypothèses'!$C$54)+(SUMIF('Calcul'!$B$2:$B$85,2,'Calcul'!$R$2:$R$85)-MAX(0,SUMIF('Calcul'!$B$2:$B$85,2,'Calcul'!$R$2:$R$85))*'Hypothèses'!$C$54)+(SUMIF('Calcul'!$B$2:$B$85,3,'Calcul'!$R$2:$R$85)-MAX(0,SUMIF('Calcul'!$B$2:$B$85,3,'Calcul'!$R$2:$R$85))*'Hypothèses'!$C$54)+(SUMIF('Calcul'!$B$2:$B$85,4,'Calcul'!$R$2:$R$85)-MAX(0,SUMIF('Calcul'!$B$2:$B$85,4,'Calcul'!$R$2:$R$85))*'Hypothèses'!$C$54)+(SUMIF('Calcul'!$B$2:$B$85,5,'Calcul'!$R$2:$R$85)-MAX(0,SUMIF('Calcul'!$B$2:$B$85,5,'Calcul'!$R$2:$R$85))*'Hypothèses'!$C$54)) | H11: =(1-'Hypothèses'!$C$56)*((SUMIF('Calcul'!$B$2:$B$85,1,'Calcul'!$R$2:$R$85)-MAX(0,SUMIF('Calcul'!$B$2:$B$85,1,'Calcul'!$R$2:$R$85))*'Hypothèses'!$C$54)+(SUMIF('Calcul'!$B$2:$B$85,2,'Calcul'!$R$2:$R$85)-MAX(0,SUMIF('Calcul'!$B$2:$B$85,2,'Calcul'!$R$2:$R$85))*'Hypothèses'!$C$54)+(SUMIF('Calcul'!$B$2:$B$85,3,'Calcul'!$R$2:$R$85)-MAX(0,SUMIF('Calcul'!$B$2:$B$85,3,'Calcul'!$R$2:$R$85))*'Hypothèses'!$C$54)+(SUMIF('Calcul'!$B$2:$B$85,4,'Calcul'!$R$2:$R$85)-MAX(0,SUMIF('Calcul'!$B$2:$B$85,4,'Calcul'!$R$2:$R$85))*'Hypothèses'!$C$54)+(SUMIF('Calcul'!$B$2:$B$85,5,'Calcul'!$R$2:$R$85)-MAX(0,SUMIF('Calcul'!$B$2:$B$85,5,'Calcul'!$R$2:$R$85))*'Hypothèses'!$C$54)+(SUMIF('Calcul'!$B$2:$B$85,6,'Calcul'!$R$2:$R$85)-MAX(0,SUMIF('Calcul'!$B$2:$B$85,6,'Calcul'!$R$2:$R$85))*'Hypothèses'!$C$54)) | I11: =(1-'Hypothèses'!$C$56)*((SUMIF('Calcul'!$B$2:$B$85,1,'Calcul'!$R$2:$R$85)-MAX(0,SUMIF('Calcul'!$B$2:$B$85,1,'Calcul'!$R$2:$R$85))*'Hypothèses'!$C$54)+(SUMIF('Calcul'!$B$2:$B$85,2,'Calcul'!$R$2:$R$85)-MAX(0,SUMIF('Calcul'!$B$2:$B$85,2,'Calcul'!$R$2:$R$85))*'Hypothèses'!$C$54)+(SUMIF('Calcul'!$B$2:$B$85,3,'Calcul'!$R$2:$R$85)-MAX(0,SUMIF('Calcul'!$B$2:$B$85,3,'Calcul'!$R$2:$R$85))*'Hypothèses'!$C$54)+(SUMIF('Calcul'!$B$2:$B$85,4,'Calcul'!$R$2:$R$85)-MAX(0,SUMIF('Calcul'!$B$2:$B$85,4,'Calcul'!$R$2:$R$85))*'Hypothèses'!$C$54)+(SUMIF('Calcul'!$B$2:$B$85,5,'Calcul'!$R$2:$R$85)-MAX(0,SUMIF('Calcul'!$B$2:$B$85,5,'Calcul'!$R$2:$R$85))*'Hypothèses'!$C$54)+(SUMIF('Calcul'!$B$2:$B$85,6,'Calcul'!$R$2:$R$85)-MAX(0,SUMIF('Calcul'!$B$2:$B$85,6,'Calcul'!$R$2:$R$85))*'Hypothèses'!$C$54)+(SUMIF('Calcul'!$B$2:$B$85,7,'Calcul'!$R$2:$R$85)-MAX(0,SUMIF('Calcul'!$B$2:$B$85,7,'Calcul'!$R$2:$R$85))*'Hypothèses'!$C$54))
B12: Total des capitaux propres | C12: =C10+C11 | D12: =D10+D11 | E12: =E10+E11 | F12: =F10+F11 | G12: =G10+G11 | H12: =H10+H11 | I12: =I10+I11 | J12: =SUM(C12:I12)
B13: Passifs courants — dividendes à payer | C13: ='Hypothèses'!$C$56*(SUMIF('Calcul'!$B$2:$B$85,1,'Calcul'!$R$2:$R$85)-MAX(0,SUMIF('Calcul'!$B$2:$B$85,1,'Calcul'!$R$2:$R$85))*'Hypothèses'!$C$54) | D13: ='Hypothèses'!$C$56*(SUMIF('Calcul'!$B$2:$B$85,2,'Calcul'!$R$2:$R$85)-MAX(0,SUMIF('Calcul'!$B$2:$B$85,2,'Calcul'!$R$2:$R$85))*'Hypothèses'!$C$54) | E13: ='Hypothèses'!$C$56*(SUMIF('Calcul'!$B$2:$B$85,3,'Calcul'!$R$2:$R$85)-MAX(0,SUMIF('Calcul'!$B$2:$B$85,3,'Calcul'!$R$2:$R$85))*'Hypothèses'!$C$54) | F13: ='Hypothèses'!$C$56*(SUMIF('Calcul'!$B$2:$B$85,4,'Calcul'!$R$2:$R$85)-MAX(0,SUMIF('Calcul'!$B$2:$B$85,4,'Calcul'!$R$2:$R$85))*'Hypothèses'!$C$54) | G13: ='Hypothèses'!$C$56*(SUMIF('Calcul'!$B$2:$B$85,5,'Calcul'!$R$2:$R$85)-MAX(0,SUMIF('Calcul'!$B$2:$B$85,5,'Calcul'!$R$2:$R$85))*'Hypothèses'!$C$54) | H13: ='Hypothèses'!$C$56*(SUMIF('Calcul'!$B$2:$B$85,6,'Calcul'!$R$2:$R$85)-MAX(0,SUMIF('Calcul'!$B$2:$B$85,6,'Calcul'!$R$2:$R$85))*'Hypothèses'!$C$54) | I13: ='Hypothèses'!$C$56*(SUMIF('Calcul'!$B$2:$B$85,7,'Calcul'!$R$2:$R$85)-MAX(0,SUMIF('Calcul'!$B$2:$B$85,7,'Calcul'!$R$2:$R$85))*'Hypothèses'!$C$54)
B14: Passifs courants — impôt à payer (exigible N+1) | C14: =MAX(0,SUMIF('Calcul'!$B$2:$B$85,1,'Calcul'!$R$2:$R$85))*'Hypothèses'!$C$54 | D14: =MAX(0,SUMIF('Calcul'!$B$2:$B$85,2,'Calcul'!$R$2:$R$85))*'Hypothèses'!$C$54 | E14: =MAX(0,SUMIF('Calcul'!$B$2:$B$85,3,'Calcul'!$R$2:$R$85))*'Hypothèses'!$C$54 | F14: =MAX(0,SUMIF('Calcul'!$B$2:$B$85,4,'Calcul'!$R$2:$R$85))*'Hypothèses'!$C$54 | G14: =MAX(0,SUMIF('Calcul'!$B$2:$B$85,5,'Calcul'!$R$2:$R$85))*'Hypothèses'!$C$54 | H14: =MAX(0,SUMIF('Calcul'!$B$2:$B$85,6,'Calcul'!$R$2:$R$85))*'Hypothèses'!$C$54 | I14: =MAX(0,SUMIF('Calcul'!$B$2:$B$85,7,'Calcul'!$R$2:$R$85))*'Hypothèses'!$C$54
B15: Total des passifs courants | C15: =C13+C14 | D15: =D13+D14 | E15: =E13+E14 | F15: =F13+F14 | G15: =G13+G14 | H15: =H13+H14 | I15: =I13+I14 | J15: =SUM(C15:I15)
B16: TOTAL CAPITAUX PROPRES & PASSIFS | C16: =C12+C15 | D16: =D12+D15 | E16: =E12+E15 | F16: =F12+F15 | G16: =G12+G15 | H16: =H12+H15 | I16: =I12+I15
B17: Contrôle (Actif − Passif ≈ 0) | C17: =C8-C16 | D17: =D8-D16 | E17: =E8-E16 | F17: =F8-F16 | G17: =G8-G16 | H17: =H8-H16 | I17: =I8-I16

Sheet Flux de trésorerie
B1: État de flux de trésorerie prévisionnel
B2: Présentation par activité (norme tunisienne). En DT — aucun flux d'investissement : les machines sont en leasing.
C4: An 1 | D4: An 2 | E4: An 3 | F4: An 4 | G4: An 5 | H4: An 6 | I4: An 7 | J4: Total 7 ans
B5: FLUX LIÉS À L'EXPLOITATION
B6: EBITDA (capacité d'autofinancement) | C6: =SUMIF('Calcul'!$B$2:$B$85,1,'Calcul'!$R$2:$R$85) | D6: =SUMIF('Calcul'!$B$2:$B$85,2,'Calcul'!$R$2:$R$85) | E6: =SUMIF('Calcul'!$B$2:$B$85,3,'Calcul'!$R$2:$R$85) | F6: =SUMIF('Calcul'!$B$2:$B$85,4,'Calcul'!$R$2:$R$85) | G6: =SUMIF('Calcul'!$B$2:$B$85,5,'Calcul'!$R$2:$R$85) | H6: =SUMIF('Calcul'!$B$2:$B$85,6,'Calcul'!$R$2:$R$85) | I6: =SUMIF('Calcul'!$B$2:$B$85,7,'Calcul'!$R$2:$R$85) | J6: =SUM(C6:I6)
B7: (−) Impôt décaissé sur l'exercice | C7: =-SUMIF('Calcul'!$B$2:$B$85,1,'Calcul'!$S$2:$S$85) | D7: =-SUMIF('Calcul'!$B$2:$B$85,2,'Calcul'!$S$2:$S$85) | E7: =-SUMIF('Calcul'!$B$2:$B$85,3,'Calcul'!$S$2:$S$85) | F7: =-SUMIF('Calcul'!$B$2:$B$85,4,'Calcul'!$S$2:$S$85) | G7: =-SUMIF('Calcul'!$B$2:$B$85,5,'Calcul'!$S$2:$S$85) | H7: =-SUMIF('Calcul'!$B$2:$B$85,6,'Calcul'!$S$2:$S$85) | I7: =-SUMIF('Calcul'!$B$2:$B$85,7,'Calcul'!$S$2:$S$85) | J7: =SUM(C7:I7)
B8: Flux net de trésorerie d'exploitation | C8: =C6+C7 | D8: =D6+D7 | E8: =E6+E7 | F8: =F6+F7 | G8: =G6+G7 | H8: =H6+H7 | I8: =I6+I7 | J8: =SUM(C8:I8)
B9: FLUX LIÉS À L'INVESTISSEMENT
B10: Acquisitions d'immobilisations (machines en leasing) | C10: =0 | D10: =0 | E10: =0 | F10: =0 | G10: =0 | H10: =0 | I10: =0 | J10: =SUM(C10:I10)
B11: Flux net de trésorerie d'investissement | C11: =0 | D11: =0 | E11: =0 | F11: =0 | G11: =0 | H11: =0 | I11: =0 | J11: =SUM(C11:I11)
B12: FLUX LIÉS AU FINANCEMENT
B13: Apport en capital | C13: ='Hypothèses'!$C$55 | D13: =0 | E13: =0 | F13: =0 | G13: =0 | H13: =0 | I13: =0 | J13: =SUM(C13:I13)
B14: Dividendes versés (au titre de l'exercice N-1) | C14: =0 | D14: =-'Hypothèses'!$C$56*(SUMIF('Calcul'!$B$2:$B$85,1,'Calcul'!$R$2:$R$85)-MAX(0,SUMIF('Calcul'!$B$2:$B$85,1,'Calcul'!$R$2:$R$85))*'Hypothèses'!$C$54) | E14: =-'Hypothèses'!$C$56*(SUMIF('Calcul'!$B$2:$B$85,2,'Calcul'!$R$2:$R$85)-MAX(0,SUMIF('Calcul'!$B$2:$B$85,2,'Calcul'!$R$2:$R$85))*'Hypothèses'!$C$54) | F14: =-'Hypothèses'!$C$56*(SUMIF('Calcul'!$B$2:$B$85,3,'Calcul'!$R$2:$R$85)-MAX(0,SUMIF('Calcul'!$B$2:$B$85,3,'Calcul'!$R$2:$R$85))*'Hypothèses'!$C$54) | G14: =-'Hypothèses'!$C$56*(SUMIF('Calcul'!$B$2:$B$85,4,'Calcul'!$R$2:$R$85)-MAX(0,SUMIF('Calcul'!$B$2:$B$85,4,'Calcul'!$R$2:$R$85))*'Hypothèses'!$C$54) | H14: =-'Hypothèses'!$C$56*(SUMIF('Calcul'!$B$2:$B$85,5,'Calcul'!$R$2:$R$85)-MAX(0,SUMIF('Calcul'!$B$2:$B$85,5,'Calcul'!$R$2:$R$85))*'Hypothèses'!$C$54) | I14: =-'Hypothèses'!$C$56*(SUMIF('Calcul'!$B$2:$B$85,6,'Calcul'!$R$2:$R$85)-MAX(0,SUMIF('Calcul'!$B$2:$B$85,6,'Calcul'!$R$2:$R$85))*'Hypothèses'!$C$54) | J14: =SUM(C14:I14)
B15: Flux net de trésorerie de financement | C15: =C13+C14 | D15: =D13+D14 | E15: =E13+E14 | F15: =F13+F14 | G15: =G13+G14 | H15: =H13+H14 | I15: =I13+I14 | J15: =SUM(C15:I15)
B16: VARIATION DE TRÉSORERIE | C16: =C8+C11+C15 | D16: =D8+D11+D15 | E16: =E8+E11+E15 | F16: =F8+F11+F15 | G16: =G8+G11+G15 | H16: =H8+H11+H15 | I16: =I8+I11+I15 | J16: =SUM(C16:I16)
B17: Trésorerie à l'ouverture | C17: =0 | D17: =C18 | E17: =D18 | F17: =E18 | G17: =F18 | H17: =G18 | I17: =H18
B18: Trésorerie à la clôture | C18: =C17+C16 | D18: =D17+D16 | E18: =E17+E16 | F18: =F17+F16 | G18: =G17+G16 | H18: =H17+H16 | I18: =I17+I16
B20: Trésorerie minimale sur 84 mois (avant distributions) | C20: =MIN('Calcul'!$T$2:$T$85) | D20: → le capital de 300 k suffit comme fonds de roulement, sans dette bancaire

Sheet Ratios financiers
B1: Ratios & indicateurs financiers
B2: Agrégats et ratios usuels d'analyse crédit (EBITDA, marges, couverture, rentabilité). Recalcul automatique.
C4: An 1 | D4: An 2 | E4: An 3 | F4: An 4 | G4: An 5 | H4: An 6 | I4: An 7 | J4: Total 7 ans
B5: SOLDES & AGRÉGATS
B6: Chiffre d'affaires (revenus) | C6: =SUMIF('Calcul'!$B$2:$B$85,1,'Calcul'!$H$2:$H$85) | D6: =SUMIF('Calcul'!$B$2:$B$85,2,'Calcul'!$H$2:$H$85) | E6: =SUMIF('Calcul'!$B$2:$B$85,3,'Calcul'!$H$2:$H$85) | F6: =SUMIF('Calcul'!$B$2:$B$85,4,'Calcul'!$H$2:$H$85) | G6: =SUMIF('Calcul'!$B$2:$B$85,5,'Calcul'!$H$2:$H$85) | H6: =SUMIF('Calcul'!$B$2:$B$85,6,'Calcul'!$H$2:$H$85) | I6: =SUMIF('Calcul'!$B$2:$B$85,7,'Calcul'!$H$2:$H$85) | J6: =SUM(C6:I6)
B7: Croissance du chiffre d'affaires | C7: ="—" | D7: =SUMIF('Calcul'!$B$2:$B$85,2,'Calcul'!$H$2:$H$85)/SUMIF('Calcul'!$B$2:$B$85,1,'Calcul'!$H$2:$H$85)-1 | E7: =SUMIF('Calcul'!$B$2:$B$85,3,'Calcul'!$H$2:$H$85)/SUMIF('Calcul'!$B$2:$B$85,2,'Calcul'!$H$2:$H$85)-1 | F7: =SUMIF('Calcul'!$B$2:$B$85,4,'Calcul'!$H$2:$H$85)/SUMIF('Calcul'!$B$2:$B$85,3,'Calcul'!$H$2:$H$85)-1 | G7: =SUMIF('Calcul'!$B$2:$B$85,5,'Calcul'!$H$2:$H$85)/SUMIF('Calcul'!$B$2:$B$85,4,'Calcul'!$H$2:$H$85)-1 | H7: =SUMIF('Calcul'!$B$2:$B$85,6,'Calcul'!$H$2:$H$85)/SUMIF('Calcul'!$B$2:$B$85,5,'Calcul'!$H$2:$H$85)-1 | I7: =SUMIF('Calcul'!$B$2:$B$85,7,'Calcul'!$H$2:$H$85)/SUMIF('Calcul'!$B$2:$B$85,6,'Calcul'!$H$2:$H$85)-1
B8: EBITDA (excédent brut d'exploitation) | C8: =SUMIF('Calcul'!$B$2:$B$85,1,'Calcul'!$R$2:$R$85) | D8: =SUMIF('Calcul'!$B$2:$B$85,2,'Calcul'!$R$2:$R$85) | E8: =SUMIF('Calcul'!$B$2:$B$85,3,'Calcul'!$R$2:$R$85) | F8: =SUMIF('Calcul'!$B$2:$B$85,4,'Calcul'!$R$2:$R$85) | G8: =SUMIF('Calcul'!$B$2:$B$85,5,'Calcul'!$R$2:$R$85) | H8: =SUMIF('Calcul'!$B$2:$B$85,6,'Calcul'!$R$2:$R$85) | I8: =SUMIF('Calcul'!$B$2:$B$85,7,'Calcul'!$R$2:$R$85) | J8: =SUM(C8:I8)
B9: EBIT (résultat d'exploitation) | C9: =SUMIF('Calcul'!$B$2:$B$85,1,'Calcul'!$R$2:$R$85) | D9: =SUMIF('Calcul'!$B$2:$B$85,2,'Calcul'!$R$2:$R$85) | E9: =SUMIF('Calcul'!$B$2:$B$85,3,'Calcul'!$R$2:$R$85) | F9: =SUMIF('Calcul'!$B$2:$B$85,4,'Calcul'!$R$2:$R$85) | G9: =SUMIF('Calcul'!$B$2:$B$85,5,'Calcul'!$R$2:$R$85) | H9: =SUMIF('Calcul'!$B$2:$B$85,6,'Calcul'!$R$2:$R$85) | I9: =SUMIF('Calcul'!$B$2:$B$85,7,'Calcul'!$R$2:$R$85) | J9: =SUM(C9:I9)
B10: Capacité d'autofinancement (CAF) | C10: =(SUMIF('Calcul'!$B$2:$B$85,1,'Calcul'!$R$2:$R$85)-MAX(0,SUMIF('Calcul'!$B$2:$B$85,1,'Calcul'!$R$2:$R$85))*'Hypothèses'!$C$54) | D10: =(SUMIF('Calcul'!$B$2:$B$85,2,'Calcul'!$R$2:$R$85)-MAX(0,SUMIF('Calcul'!$B$2:$B$85,2,'Calcul'!$R$2:$R$85))*'Hypothèses'!$C$54) | E10: =(SUMIF('Calcul'!$B$2:$B$85,3,'Calcul'!$R$2:$R$85)-MAX(0,SUMIF('Calcul'!$B$2:$B$85,3,'Calcul'!$R$2:$R$85))*'Hypothèses'!$C$54) | F10: =(SUMIF('Calcul'!$B$2:$B$85,4,'Calcul'!$R$2:$R$85)-MAX(0,SUMIF('Calcul'!$B$2:$B$85,4,'Calcul'!$R$2:$R$85))*'Hypothèses'!$C$54) | G10: =(SUMIF('Calcul'!$B$2:$B$85,5,'Calcul'!$R$2:$R$85)-MAX(0,SUMIF('Calcul'!$B$2:$B$85,5,'Calcul'!$R$2:$R$85))*'Hypothèses'!$C$54) | H10: =(SUMIF('Calcul'!$B$2:$B$85,6,'Calcul'!$R$2:$R$85)-MAX(0,SUMIF('Calcul'!$B$2:$B$85,6,'Calcul'!$R$2:$R$85))*'Hypothèses'!$C$54) | I10: =(SUMIF('Calcul'!$B$2:$B$85,7,'Calcul'!$R$2:$R$85)-MAX(0,SUMIF('Calcul'!$B$2:$B$85,7,'Calcul'!$R$2:$R$85))*'Hypothèses'!$C$54) | J10: =SUM(C10:I10)
B11: Résultat net | C11: =(SUMIF('Calcul'!$B$2:$B$85,1,'Calcul'!$R$2:$R$85)-MAX(0,SUMIF('Calcul'!$B$2:$B$85,1,'Calcul'!$R$2:$R$85))*'Hypothèses'!$C$54) | D11: =(SUMIF('Calcul'!$B$2:$B$85,2,'Calcul'!$R$2:$R$85)-MAX(0,SUMIF('Calcul'!$B$2:$B$85,2,'Calcul'!$R$2:$R$85))*'Hypothèses'!$C$54) | E11: =(SUMIF('Calcul'!$B$2:$B$85,3,'Calcul'!$R$2:$R$85)-MAX(0,SUMIF('Calcul'!$B$2:$B$85,3,'Calcul'!$R$2:$R$85))*'Hypothèses'!$C$54) | F11: =(SUMIF('Calcul'!$B$2:$B$85,4,'Calcul'!$R$2:$R$85)-MAX(0,SUMIF('Calcul'!$B$2:$B$85,4,'Calcul'!$R$2:$R$85))*'Hypothèses'!$C$54) | G11: =(SUMIF('Calcul'!$B$2:$B$85,5,'Calcul'!$R$2:$R$85)-MAX(0,SUMIF('Calcul'!$B$2:$B$85,5,'Calcul'!$R$2:$R$85))*'Hypothèses'!$C$54) | H11: =(SUMIF('Calcul'!$B$2:$B$85,6,'Calcul'!$R$2:$R$85)-MAX(0,SUMIF('Calcul'!$B$2:$B$85,6,'Calcul'!$R$2:$R$85))*'Hypothèses'!$C$54) | I11: =(SUMIF('Calcul'!$B$2:$B$85,7,'Calcul'!$R$2:$R$85)-MAX(0,SUMIF('Calcul'!$B$2:$B$85,7,'Calcul'!$R$2:$R$85))*'Hypothèses'!$C$54) | J11: =SUM(C11:I11)
B12: MARGES
B13: Marge d'EBITDA (% du CA) | C13: =SUMIF('Calcul'!$B$2:$B$85,1,'Calcul'!$R$2:$R$85)/SUMIF('Calcul'!$B$2:$B$85,1,'Calcul'!$H$2:$H$85) | D13: =SUMIF('Calcul'!$B$2:$B$85,2,'Calcul'!$R$2:$R$85)/SUMIF('Calcul'!$B$2:$B$85,2,'Calcul'!$H$2:$H$85) | E13: =SUMIF('Calcul'!$B$2:$B$85,3,'Calcul'!$R$2:$R$85)/SUMIF('Calcul'!$B$2:$B$85,3,'Calcul'!$H$2:$H$85) | F13: =SUMIF('Calcul'!$B$2:$B$85,4,'Calcul'!$R$2:$R$85)/SUMIF('Calcul'!$B$2:$B$85,4,'Calcul'!$H$2:$H$85) | G13: =SUMIF('Calcul'!$B$2:$B$85,5,'Calcul'!$R$2:$R$85)/SUMIF('Calcul'!$B$2:$B$85,5,'Calcul'!$H$2:$H$85) | H13: =SUMIF('Calcul'!$B$2:$B$85,6,'Calcul'!$R$2:$R$85)/SUMIF('Calcul'!$B$2:$B$85,6,'Calcul'!$H$2:$H$85) | I13: =SUMIF('Calcul'!$B$2:$B$85,7,'Calcul'!$R$2:$R$85)/SUMIF('Calcul'!$B$2:$B$85,7,'Calcul'!$H$2:$H$85)
B14: Marge nette (% du CA) | C14: =(SUMIF('Calcul'!$B$2:$B$85,1,'Calcul'!$R$2:$R$85)-MAX(0,SUMIF('Calcul'!$B$2:$B$85,1,'Calcul'!$R$2:$R$85))*'Hypothèses'!$C$54)/SUMIF('Calcul'!$B$2:$B$85,1,'Calcul'!$H$2:$H$85) | D14: =(SUMIF('Calcul'!$B$2:$B$85,2,'Calcul'!$R$2:$R$85)-MAX(0,SUMIF('Calcul'!$B$2:$B$85,2,'Calcul'!$R$2:$R$85))*'Hypothèses'!$C$54)/SUMIF('Calcul'!$B$2:$B$85,2,'Calcul'!$H$2:$H$85) | E14: =(SUMIF('Calcul'!$B$2:$B$85,3,'Calcul'!$R$2:$R$85)-MAX(0,SUMIF('Calcul'!$B$2:$B$85,3,'Calcul'!$R$2:$R$85))*'Hypothèses'!$C$54)/SUMIF('Calcul'!$B$2:$B$85,3,'Calcul'!$H$2:$H$85) | F14: =(SUMIF('Calcul'!$B$2:$B$85,4,'Calcul'!$R$2:$R$85)-MAX(0,SUMIF('Calcul'!$B$2:$B$85,4,'Calcul'!$R$2:$R$85))*'Hypothèses'!$C$54)/SUMIF('Calcul'!$B$2:$B$85,4,'Calcul'!$H$2:$H$85) | G14: =(SUMIF('Calcul'!$B$2:$B$85,5,'Calcul'!$R$2:$R$85)-MAX(0,SUMIF('Calcul'!$B$2:$B$85,5,'Calcul'!$R$2:$R$85))*'Hypothèses'!$C$54)/SUMIF('Calcul'!$B$2:$B$85,5,'Calcul'!$H$2:$H$85) | H14: =(SUMIF('Calcul'!$B$2:$B$85,6,'Calcul'!$R$2:$R$85)-MAX(0,SUMIF('Calcul'!$B$2:$B$85,6,'Calcul'!$R$2:$R$85))*'Hypothèses'!$C$54)/SUMIF('Calcul'!$B$2:$B$85,6,'Calcul'!$H$2:$H$85) | I14: =(SUMIF('Calcul'!$B$2:$B$85,7,'Calcul'!$R$2:$R$85)-MAX(0,SUMIF('Calcul'!$B$2:$B$85,7,'Calcul'!$R$2:$R$85))*'Hypothèses'!$C$54)/SUMIF('Calcul'!$B$2:$B$85,7,'Calcul'!$H$2:$H$85)
B15: COUVERTURE DU SERVICE LEASING (clé bailleur)
B16: Engagements leasing (loyers machines + véhicule) | C16: =SUMIF('Calcul'!$B$2:$B$85,1,'Calcul'!$J$2:$J$85)+SUMIF('Calcul'!$B$2:$B$85,1,'Calcul'!$Q$2:$Q$85) | D16: =SUMIF('Calcul'!$B$2:$B$85,2,'Calcul'!$J$2:$J$85)+SUMIF('Calcul'!$B$2:$B$85,2,'Calcul'!$Q$2:$Q$85) | E16: =SUMIF('Calcul'!$B$2:$B$85,3,'Calcul'!$J$2:$J$85)+SUMIF('Calcul'!$B$2:$B$85,3,'Calcul'!$Q$2:$Q$85) | F16: =SUMIF('Calcul'!$B$2:$B$85,4,'Calcul'!$J$2:$J$85)+SUMIF('Calcul'!$B$2:$B$85,4,'Calcul'!$Q$2:$Q$85) | G16: =SUMIF('Calcul'!$B$2:$B$85,5,'Calcul'!$J$2:$J$85)+SUMIF('Calcul'!$B$2:$B$85,5,'Calcul'!$Q$2:$Q$85) | H16: =SUMIF('Calcul'!$B$2:$B$85,6,'Calcul'!$J$2:$J$85)+SUMIF('Calcul'!$B$2:$B$85,6,'Calcul'!$Q$2:$Q$85) | I16: =SUMIF('Calcul'!$B$2:$B$85,7,'Calcul'!$J$2:$J$85)+SUMIF('Calcul'!$B$2:$B$85,7,'Calcul'!$Q$2:$Q$85) | J16: =SUM(C16:I16)
B17: DSCR (EBITDA avant loyers / loyers) | C17: =(SUMIF('Calcul'!$B$2:$B$85,1,'Calcul'!$R$2:$R$85)+SUMIF('Calcul'!$B$2:$B$85,1,'Calcul'!$J$2:$J$85)+SUMIF('Calcul'!$B$2:$B$85,1,'Calcul'!$Q$2:$Q$85))/(SUMIF('Calcul'!$B$2:$B$85,1,'Calcul'!$J$2:$J$85)+SUMIF('Calcul'!$B$2:$B$85,1,'Calcul'!$Q$2:$Q$85)) | D17: =(SUMIF('Calcul'!$B$2:$B$85,2,'Calcul'!$R$2:$R$85)+SUMIF('Calcul'!$B$2:$B$85,2,'Calcul'!$J$2:$J$85)+SUMIF('Calcul'!$B$2:$B$85,2,'Calcul'!$Q$2:$Q$85))/(SUMIF('Calcul'!$B$2:$B$85,2,'Calcul'!$J$2:$J$85)+SUMIF('Calcul'!$B$2:$B$85,2,'Calcul'!$Q$2:$Q$85)) | E17: =(SUMIF('Calcul'!$B$2:$B$85,3,'Calcul'!$R$2:$R$85)+SUMIF('Calcul'!$B$2:$B$85,3,'Calcul'!$J$2:$J$85)+SUMIF('Calcul'!$B$2:$B$85,3,'Calcul'!$Q$2:$Q$85))/(SUMIF('Calcul'!$B$2:$B$85,3,'Calcul'!$J$2:$J$85)+SUMIF('Calcul'!$B$2:$B$85,3,'Calcul'!$Q$2:$Q$85)) | F17: =(SUMIF('Calcul'!$B$2:$B$85,4,'Calcul'!$R$2:$R$85)+SUMIF('Calcul'!$B$2:$B$85,4,'Calcul'!$J$2:$J$85)+SUMIF('Calcul'!$B$2:$B$85,4,'Calcul'!$Q$2:$Q$85))/(SUMIF('Calcul'!$B$2:$B$85,4,'Calcul'!$J$2:$J$85)+SUMIF('Calcul'!$B$2:$B$85,4,'Calcul'!$Q$2:$Q$85)) | G17: =(SUMIF('Calcul'!$B$2:$B$85,5,'Calcul'!$R$2:$R$85)+SUMIF('Calcul'!$B$2:$B$85,5,'Calcul'!$J$2:$J$85)+SUMIF('Calcul'!$B$2:$B$85,5,'Calcul'!$Q$2:$Q$85))/(SUMIF('Calcul'!$B$2:$B$85,5,'Calcul'!$J$2:$J$85)+SUMIF('Calcul'!$B$2:$B$85,5,'Calcul'!$Q$2:$Q$85)) | H17: =(SUMIF('Calcul'!$B$2:$B$85,6,'Calcul'!$R$2:$R$85)+SUMIF('Calcul'!$B$2:$B$85,6,'Calcul'!$J$2:$J$85)+SUMIF('Calcul'!$B$2:$B$85,6,'Calcul'!$Q$2:$Q$85))/(SUMIF('Calcul'!$B$2:$B$85,6,'Calcul'!$J$2:$J$85)+SUMIF('Calcul'!$B$2:$B$85,6,'Calcul'!$Q$2:$Q$85)) | I17: =(SUMIF('Calcul'!$B$2:$B$85,7,'Calcul'!$R$2:$R$85)+SUMIF('Calcul'!$B$2:$B$85,7,'Calcul'!$J$2:$J$85)+SUMIF('Calcul'!$B$2:$B$85,7,'Calcul'!$Q$2:$Q$85))/(SUMIF('Calcul'!$B$2:$B$85,7,'Calcul'!$J$2:$J$85)+SUMIF('Calcul'!$B$2:$B$85,7,'Calcul'!$Q$2:$Q$85)) | J17: =MIN(C17:I17)
B18: EBITDA / loyers de leasing | C18: =SUMIF('Calcul'!$B$2:$B$85,1,'Calcul'!$R$2:$R$85)/(SUMIF('Calcul'!$B$2:$B$85,1,'Calcul'!$J$2:$J$85)+SUMIF('Calcul'!$B$2:$B$85,1,'Calcul'!$Q$2:$Q$85)) | D18: =SUMIF('Calcul'!$B$2:$B$85,2,'Calcul'!$R$2:$R$85)/(SUMIF('Calcul'!$B$2:$B$85,2,'Calcul'!$J$2:$J$85)+SUMIF('Calcul'!$B$2:$B$85,2,'Calcul'!$Q$2:$Q$85)) | E18: =SUMIF('Calcul'!$B$2:$B$85,3,'Calcul'!$R$2:$R$85)/(SUMIF('Calcul'!$B$2:$B$85,3,'Calcul'!$J$2:$J$85)+SUMIF('Calcul'!$B$2:$B$85,3,'Calcul'!$Q$2:$Q$85)) | F18: =SUMIF('Calcul'!$B$2:$B$85,4,'Calcul'!$R$2:$R$85)/(SUMIF('Calcul'!$B$2:$B$85,4,'Calcul'!$J$2:$J$85)+SUMIF('Calcul'!$B$2:$B$85,4,'Calcul'!$Q$2:$Q$85)) | G18: =SUMIF('Calcul'!$B$2:$B$85,5,'Calcul'!$R$2:$R$85)/(SUMIF('Calcul'!$B$2:$B$85,5,'Calcul'!$J$2:$J$85)+SUMIF('Calcul'!$B$2:$B$85,5,'Calcul'!$Q$2:$Q$85)) | H18: =SUMIF('Calcul'!$B$2:$B$85,6,'Calcul'!$R$2:$R$85)/(SUMIF('Calcul'!$B$2:$B$85,6,'Calcul'!$J$2:$J$85)+SUMIF('Calcul'!$B$2:$B$85,6,'Calcul'!$Q$2:$Q$85)) | I18: =SUMIF('Calcul'!$B$2:$B$85,7,'Calcul'!$R$2:$R$85)/(SUMIF('Calcul'!$B$2:$B$85,7,'Calcul'!$J$2:$J$85)+SUMIF('Calcul'!$B$2:$B$85,7,'Calcul'!$Q$2:$Q$85))
B19: STRUCTURE & RENTABILITÉ
B20: Capitaux propres | C20: =('Hypothèses'!$C$55+(1-'Hypothèses'!$C$56)*((SUMIF('Calcul'!$B$2:$B$85,1,'Calcul'!$R$2:$R$85)-MAX(0,SUMIF('Calcul'!$B$2:$B$85,1,'Calcul'!$R$2:$R$85))*'Hypothèses'!$C$54))) | D20: =('Hypothèses'!$C$55+(1-'Hypothèses'!$C$56)*((SUMIF('Calcul'!$B$2:$B$85,1,'Calcul'!$R$2:$R$85)-MAX(0,SUMIF('Calcul'!$B$2:$B$85,1,'Calcul'!$R$2:$R$85))*'Hypothèses'!$C$54)+(SUMIF('Calcul'!$B$2:$B$85,2,'Calcul'!$R$2:$R$85)-MAX(0,SUMIF('Calcul'!$B$2:$B$85,2,'Calcul'!$R$2:$R$85))*'Hypothèses'!$C$54))) | E20: =('Hypothèses'!$C$55+(1-'Hypothèses'!$C$56)*((SUMIF('Calcul'!$B$2:$B$85,1,'Calcul'!$R$2:$R$85)-MAX(0,SUMIF('Calcul'!$B$2:$B$85,1,'Calcul'!$R$2:$R$85))*'Hypothèses'!$C$54)+(SUMIF('Calcul'!$B$2:$B$85,2,'Calcul'!$R$2:$R$85)-MAX(0,SUMIF('Calcul'!$B$2:$B$85,2,'Calcul'!$R$2:$R$85))*'Hypothèses'!$C$54)+(SUMIF('Calcul'!$B$2:$B$85,3,'Calcul'!$R$2:$R$85)-MAX(0,SUMIF('Calcul'!$B$2:$B$85,3,'Calcul'!$R$2:$R$85))*'Hypothèses'!$C$54))) | F20: =('Hypothèses'!$C$55+(1-'Hypothèses'!$C$56)*((SUMIF('Calcul'!$B$2:$B$85,1,'Calcul'!$R$2:$R$85)-MAX(0,SUMIF('Calcul'!$B$2:$B$85,1,'Calcul'!$R$2:$R$85))*'Hypothèses'!$C$54)+(SUMIF('Calcul'!$B$2:$B$85,2,'Calcul'!$R$2:$R$85)-MAX(0,SUMIF('Calcul'!$B$2:$B$85,2,'Calcul'!$R$2:$R$85))*'Hypothèses'!$C$54)+(SUMIF('Calcul'!$B$2:$B$85,3,'Calcul'!$R$2:$R$85)-MAX(0,SUMIF('Calcul'!$B$2:$B$85,3,'Calcul'!$R$2:$R$85))*'Hypothèses'!$C$54)+(SUMIF('Calcul'!$B$2:$B$85,4,'Calcul'!$R$2:$R$85)-MAX(0,SUMIF('Calcul'!$B$2:$B$85,4,'Calcul'!$R$2:$R$85))*'Hypothèses'!$C$54))) | G20: =('Hypothèses'!$C$55+(1-'Hypothèses'!$C$56)*((SUMIF('Calcul'!$B$2:$B$85,1,'Calcul'!$R$2:$R$85)-MAX(0,SUMIF('Calcul'!$B$2:$B$85,1,'Calcul'!$R$2:$R$85))*'Hypothèses'!$C$54)+(SUMIF('Calcul'!$B$2:$B$85,2,'Calcul'!$R$2:$R$85)-MAX(0,SUMIF('Calcul'!$B$2:$B$85,2,'Calcul'!$R$2:$R$85))*'Hypothèses'!$C$54)+(SUMIF('Calcul'!$B$2:$B$85,3,'Calcul'!$R$2:$R$85)-MAX(0,SUMIF('Calcul'!$B$2:$B$85,3,'Calcul'!$R$2:$R$85))*'Hypothèses'!$C$54)+(SUMIF('Calcul'!$B$2:$B$85,4,'Calcul'!$R$2:$R$85)-MAX(0,SUMIF('Calcul'!$B$2:$B$85,4,'Calcul'!$R$2:$R$85))*'Hypothèses'!$C$54)+(SUMIF('Calcul'!$B$2:$B$85,5,'Calcul'!$R$2:$R$85)-MAX(0,SUMIF('Calcul'!$B$2:$B$85,5,'Calcul'!$R$2:$R$85))*'Hypothèses'!$C$54))) | H20: =('Hypothèses'!$C$55+(1-'Hypothèses'!$C$56)*((SUMIF('Calcul'!$B$2:$B$85,1,'Calcul'!$R$2:$R$85)-MAX(0,SUMIF('Calcul'!$B$2:$B$85,1,'Calcul'!$R$2:$R$85))*'Hypothèses'!$C$54)+(SUMIF('Calcul'!$B$2:$B$85,2,'Calcul'!$R$2:$R$85)-MAX(0,SUMIF('Calcul'!$B$2:$B$85,2,'Calcul'!$R$2:$R$85))*'Hypothèses'!$C$54)+(SUMIF('Calcul'!$B$2:$B$85,3,'Calcul'!$R$2:$R$85)-MAX(0,SUMIF('Calcul'!$B$2:$B$85,3,'Calcul'!$R$2:$R$85))*'Hypothèses'!$C$54)+(SUMIF('Calcul'!$B$2:$B$85,4,'Calcul'!$R$2:$R$85)-MAX(0,SUMIF('Calcul'!$B$2:$B$85,4,'Calcul'!$R$2:$R$85))*'Hypothèses'!$C$54)+(SUMIF('Calcul'!$B$2:$B$85,5,'Calcul'!$R$2:$R$85)-MAX(0,SUMIF('Calcul'!$B$2:$B$85,5,'Calcul'!$R$2:$R$85))*'Hypothèses'!$C$54)+(SUMIF('Calcul'!$B$2:$B$85,6,'Calcul'!$R$2:$R$85)-MAX(0,SUMIF('Calcul'!$B$2:$B$85,6,'Calcul'!$R$2:$R$85))*'Hypothèses'!$C$54))) | I20: =('Hypothèses'!$C$55+(1-'Hypothèses'!$C$56)*((SUMIF('Calcul'!$B$2:$B$85,1,'Calcul'!$R$2:$R$85)-MAX(0,SUMIF('Calcul'!$B$2:$B$85,1,'Calcul'!$R$2:$R$85))*'Hypothèses'!$C$54)+(SUMIF('Calcul'!$B$2:$B$85,2,'Calcul'!$R$2:$R$85)-MAX(0,SUMIF('Calcul'!$B$2:$B$85,2,'Calcul'!$R$2:$R$85))*'Hypothèses'!$C$54)+(SUMIF('Calcul'!$B$2:$B$85,3,'Calcul'!$R$2:$R$85)-MAX(0,SUMIF('Calcul'!$B$2:$B$85,3,'Calcul'!$R$2:$R$85))*'Hypothèses'!$C$54)+(SUMIF('Calcul'!$B$2:$B$85,4,'Calcul'!$R$2:$R$85)-MAX(0,SUMIF('Calcul'!$B$2:$B$85,4,'Calcul'!$R$2:$R$85))*'Hypothèses'!$C$54)+(SUMIF('Calcul'!$B$2:$B$85,5,'Calcul'!$R$2:$R$85)-MAX(0,SUMIF('Calcul'!$B$2:$B$85,5,'Calcul'!$R$2:$R$85))*'Hypothèses'!$C$54)+(SUMIF('Calcul'!$B$2:$B$85,6,'Calcul'!$R$2:$R$85)-MAX(0,SUMIF('Calcul'!$B$2:$B$85,6,'Calcul'!$R$2:$R$85))*'Hypothèses'!$C$54)+(SUMIF('Calcul'!$B$2:$B$85,7,'Calcul'!$R$2:$R$85)-MAX(0,SUMIF('Calcul'!$B$2:$B$85,7,'Calcul'!$R$2:$R$85))*'Hypothèses'!$C$54)))
B21: Dette financière bancaire | C21: =0 | D21: =0 | E21: =0 | F21: =0 | G21: =0 | H21: =0 | I21: =0
B22: Gearing (dette / capitaux propres) | C22: =0 | D22: =0 | E22: =0 | F22: =0 | G22: =0 | H22: =0 | I22: =0
B23: Trésorerie nette de clôture | C23: ='Calcul'!$T$13 | D23: ='Calcul'!$T$25-'Hypothèses'!$C$56*((SUMIF('Calcul'!$B$2:$B$85,1,'Calcul'!$R$2:$R$85)-MAX(0,SUMIF('Calcul'!$B$2:$B$85,1,'Calcul'!$R$2:$R$85))*'Hypothèses'!$C$54)) | E23: ='Calcul'!$T$37-'Hypothèses'!$C$56*((SUMIF('Calcul'!$B$2:$B$85,1,'Calcul'!$R$2:$R$85)-MAX(0,SUMIF('Calcul'!$B$2:$B$85,1,'Calcul'!$R$2:$R$85))*'Hypothèses'!$C$54)+(SUMIF('Calcul'!$B$2:$B$85,2,'Calcul'!$R$2:$R$85)-MAX(0,SUMIF('Calcul'!$B$2:$B$85,2,'Calcul'!$R$2:$R$85))*'Hypothèses'!$C$54)) | F23: ='Calcul'!$T$49-'Hypothèses'!$C$56*((SUMIF('Calcul'!$B$2:$B$85,1,'Calcul'!$R$2:$R$85)-MAX(0,SUMIF('Calcul'!$B$2:$B$85,1,'Calcul'!$R$2:$R$85))*'Hypothèses'!$C$54)+(SUMIF('Calcul'!$B$2:$B$85,2,'Calcul'!$R$2:$R$85)-MAX(0,SUMIF('Calcul'!$B$2:$B$85,2,'Calcul'!$R$2:$R$85))*'Hypothèses'!$C$54)+(SUMIF('Calcul'!$B$2:$B$85,3,'Calcul'!$R$2:$R$85)-MAX(0,SUMIF('Calcul'!$B$2:$B$85,3,'Calcul'!$R$2:$R$85))*'Hypothèses'!$C$54)) | G23: ='Calcul'!$T$61-'Hypothèses'!$C$56*((SUMIF('Calcul'!$B$2:$B$85,1,'Calcul'!$R$2:$R$85)-MAX(0,SUMIF('Calcul'!$B$2:$B$85,1,'Calcul'!$R$2:$R$85))*'Hypothèses'!$C$54)+(SUMIF('Calcul'!$B$2:$B$85,2,'Calcul'!$R$2:$R$85)-MAX(0,SUMIF('Calcul'!$B$2:$B$85,2,'Calcul'!$R$2:$R$85))*'Hypothèses'!$C$54)+(SUMIF('Calcul'!$B$2:$B$85,3,'Calcul'!$R$2:$R$85)-MAX(0,SUMIF('Calcul'!$B$2:$B$85,3,'Calcul'!$R$2:$R$85))*'Hypothèses'!$C$54)+(SUMIF('Calcul'!$B$2:$B$85,4,'Calcul'!$R$2:$R$85)-MAX(0,SUMIF('Calcul'!$B$2:$B$85,4,'Calcul'!$R$2:$R$85))*'Hypothèses'!$C$54)) | H23: ='Calcul'!$T$73-'Hypothèses'!$C$56*((SUMIF('Calcul'!$B$2:$B$85,1,'Calcul'!$R$2:$R$85)-MAX(0,SUMIF('Calcul'!$B$2:$B$85,1,'Calcul'!$R$2:$R$85))*'Hypothèses'!$C$54)+(SUMIF('Calcul'!$B$2:$B$85,2,'Calcul'!$R$2:$R$85)-MAX(0,SUMIF('Calcul'!$B$2:$B$85,2,'Calcul'!$R$2:$R$85))*'Hypothèses'!$C$54)+(SUMIF('Calcul'!$B$2:$B$85,3,'Calcul'!$R$2:$R$85)-MAX(0,SUMIF('Calcul'!$B$2:$B$85,3,'Calcul'!$R$2:$R$85))*'Hypothèses'!$C$54)+(SUMIF('Calcul'!$B$2:$B$85,4,'Calcul'!$R$2:$R$85)-MAX(0,SUMIF('Calcul'!$B$2:$B$85,4,'Calcul'!$R$2:$R$85))*'Hypothèses'!$C$54)+(SUMIF('Calcul'!$B$2:$B$85,5,'Calcul'!$R$2:$R$85)-MAX(0,SUMIF('Calcul'!$B$2:$B$85,5,'Calcul'!$R$2:$R$85))*'Hypothèses'!$C$54)) | I23: ='Calcul'!$T$85-'Hypothèses'!$C$56*((SUMIF('Calcul'!$B$2:$B$85,1,'Calcul'!$R$2:$R$85)-MAX(0,SUMIF('Calcul'!$B$2:$B$85,1,'Calcul'!$R$2:$R$85))*'Hypothèses'!$C$54)+(SUMIF('Calcul'!$B$2:$B$85,2,'Calcul'!$R$2:$R$85)-MAX(0,SUMIF('Calcul'!$B$2:$B$85,2,'Calcul'!$R$2:$R$85))*'Hypothèses'!$C$54)+(SUMIF('Calcul'!$B$2:$B$85,3,'Calcul'!$R$2:$R$85)-MAX(0,SUMIF('Calcul'!$B$2:$B$85,3,'Calcul'!$R$2:$R$85))*'Hypothèses'!$C$54)+(SUMIF('Calcul'!$B$2:$B$85,4,'Calcul'!$R$2:$R$85)-MAX(0,SUMIF('Calcul'!$B$2:$B$85,4,'Calcul'!$R$2:$R$85))*'Hypothèses'!$C$54)+(SUMIF('Calcul'!$B$2:$B$85,5,'Calcul'!$R$2:$R$85)-MAX(0,SUMIF('Calcul'!$B$2:$B$85,5,'Calcul'!$R$2:$R$85))*'Hypothèses'!$C$54)+(SUMIF('Calcul'!$B$2:$B$85,6,'Calcul'!$R$2:$R$85)-MAX(0,SUMIF('Calcul'!$B$2:$B$85,6,'Calcul'!$R$2:$R$85))*'Hypothèses'!$C$54))
B24: ROE (résultat net / capitaux propres) | C24: =(SUMIF('Calcul'!$B$2:$B$85,1,'Calcul'!$R$2:$R$85)-MAX(0,SUMIF('Calcul'!$B$2:$B$85,1,'Calcul'!$R$2:$R$85))*'Hypothèses'!$C$54)/('Hypothèses'!$C$55+(1-'Hypothèses'!$C$56)*((SUMIF('Calcul'!$B$2:$B$85,1,'Calcul'!$R$2:$R$85)-MAX(0,SUMIF('Calcul'!$B$2:$B$85,1,'Calcul'!$R$2:$R$85))*'Hypothèses'!$C$54))) | D24: =(SUMIF('Calcul'!$B$2:$B$85,2,'Calcul'!$R$2:$R$85)-MAX(0,SUMIF('Calcul'!$B$2:$B$85,2,'Calcul'!$R$2:$R$85))*'Hypothèses'!$C$54)/('Hypothèses'!$C$55+(1-'Hypothèses'!$C$56)*((SUMIF('Calcul'!$B$2:$B$85,1,'Calcul'!$R$2:$R$85)-MAX(0,SUMIF('Calcul'!$B$2:$B$85,1,'Calcul'!$R$2:$R$85))*'Hypothèses'!$C$54)+(SUMIF('Calcul'!$B$2:$B$85,2,'Calcul'!$R$2:$R$85)-MAX(0,SUMIF('Calcul'!$B$2:$B$85,2,'Calcul'!$R$2:$R$85))*'Hypothèses'!$C$54))) | E24: =(SUMIF('Calcul'!$B$2:$B$85,3,'Calcul'!$R$2:$R$85)-MAX(0,SUMIF('Calcul'!$B$2:$B$85,3,'Calcul'!$R$2:$R$85))*'Hypothèses'!$C$54)/('Hypothèses'!$C$55+(1-'Hypothèses'!$C$56)*((SUMIF('Calcul'!$B$2:$B$85,1,'Calcul'!$R$2:$R$85)-MAX(0,SUMIF('Calcul'!$B$2:$B$85,1,'Calcul'!$R$2:$R$85))*'Hypothèses'!$C$54)+(SUMIF('Calcul'!$B$2:$B$85,2,'Calcul'!$R$2:$R$85)-MAX(0,SUMIF('Calcul'!$B$2:$B$85,2,'Calcul'!$R$2:$R$85))*'Hypothèses'!$C$54)+(SUMIF('Calcul'!$B$2:$B$85,3,'Calcul'!$R$2:$R$85)-MAX(0,SUMIF('Calcul'!$B$2:$B$85,3,'Calcul'!$R$2:$R$85))*'Hypothèses'!$C$54))) | F24: =(SUMIF('Calcul'!$B$2:$B$85,4,'Calcul'!$R$2:$R$85)-MAX(0,SUMIF('Calcul'!$B$2:$B$85,4,'Calcul'!$R$2:$R$85))*'Hypothèses'!$C$54)/('Hypothèses'!$C$55+(1-'Hypothèses'!$C$56)*((SUMIF('Calcul'!$B$2:$B$85,1,'Calcul'!$R$2:$R$85)-MAX(0,SUMIF('Calcul'!$B$2:$B$85,1,'Calcul'!$R$2:$R$85))*'Hypothèses'!$C$54)+(SUMIF('Calcul'!$B$2:$B$85,2,'Calcul'!$R$2:$R$85)-MAX(0,SUMIF('Calcul'!$B$2:$B$85,2,'Calcul'!$R$2:$R$85))*'Hypothèses'!$C$54)+(SUMIF('Calcul'!$B$2:$B$85,3,'Calcul'!$R$2:$R$85)-MAX(0,SUMIF('Calcul'!$B$2:$B$85,3,'Calcul'!$R$2:$R$85))*'Hypothèses'!$C$54)+(SUMIF('Calcul'!$B$2:$B$85,4,'Calcul'!$R$2:$R$85)-MAX(0,SUMIF('Calcul'!$B$2:$B$85,4,'Calcul'!$R$2:$R$85))*'Hypothèses'!$C$54))) | G24: =(SUMIF('Calcul'!$B$2:$B$85,5,'Calcul'!$R$2:$R$85)-MAX(0,SUMIF('Calcul'!$B$2:$B$85,5,'Calcul'!$R$2:$R$85))*'Hypothèses'!$C$54)/('Hypothèses'!$C$55+(1-'Hypothèses'!$C$56)*((SUMIF('Calcul'!$B$2:$B$85,1,'Calcul'!$R$2:$R$85)-MAX(0,SUMIF('Calcul'!$B$2:$B$85,1,'Calcul'!$R$2:$R$85))*'Hypothèses'!$C$54)+(SUMIF('Calcul'!$B$2:$B$85,2,'Calcul'!$R$2:$R$85)-MAX(0,SUMIF('Calcul'!$B$2:$B$85,2,'Calcul'!$R$2:$R$85))*'Hypothèses'!$C$54)+(SUMIF('Calcul'!$B$2:$B$85,3,'Calcul'!$R$2:$R$85)-MAX(0,SUMIF('Calcul'!$B$2:$B$85,3,'Calcul'!$R$2:$R$85))*'Hypothèses'!$C$54)+(SUMIF('Calcul'!$B$2:$B$85,4,'Calcul'!$R$2:$R$85)-MAX(0,SUMIF('Calcul'!$B$2:$B$85,4,'Calcul'!$R$2:$R$85))*'Hypothèses'!$C$54)+(SUMIF('Calcul'!$B$2:$B$85,5,'Calcul'!$R$2:$R$85)-MAX(0,SUMIF('Calcul'!$B$2:$B$85,5,'Calcul'!$R$2:$R$85))*'Hypothèses'!$C$54))) | H24: =(SUMIF('Calcul'!$B$2:$B$85,6,'Calcul'!$R$2:$R$85)-MAX(0,SUMIF('Calcul'!$B$2:$B$85,6,'Calcul'!$R$2:$R$85))*'Hypothèses'!$C$54)/('Hypothèses'!$C$55+(1-'Hypothèses'!$C$56)*((SUMIF('Calcul'!$B$2:$B$85,1,'Calcul'!$R$2:$R$85)-MAX(0,SUMIF('Calcul'!$B$2:$B$85,1,'Calcul'!$R$2:$R$85))*'Hypothèses'!$C$54)+(SUMIF('Calcul'!$B$2:$B$85,2,'Calcul'!$R$2:$R$85)-MAX(0,SUMIF('Calcul'!$B$2:$B$85,2,'Calcul'!$R$2:$R$85))*'Hypothèses'!$C$54)+(SUMIF('Calcul'!$B$2:$B$85,3,'Calcul'!$R$2:$R$85)-MAX(0,SUMIF('Calcul'!$B$2:$B$85,3,'Calcul'!$R$2:$R$85))*'Hypothèses'!$C$54)+(SUMIF('Calcul'!$B$2:$B$85,4,'Calcul'!$R$2:$R$85)-MAX(0,SUMIF('Calcul'!$B$2:$B$85,4,'Calcul'!$R$2:$R$85))*'Hypothèses'!$C$54)+(SUMIF('Calcul'!$B$2:$B$85,5,'Calcul'!$R$2:$R$85)-MAX(0,SUMIF('Calcul'!$B$2:$B$85,5,'Calcul'!$R$2:$R$85))*'Hypothèses'!$C$54)+(SUMIF('Calcul'!$B$2:$B$85,6,'Calcul'!$R$2:$R$85)-MAX(0,SUMIF('Calcul'!$B$2:$B$85,6,'Calcul'!$R$2:$R$85))*'Hypothèses'!$C$54))) | I24: =(SUMIF('Calcul'!$B$2:$B$85,7,'Calcul'!$R$2:$R$85)-MAX(0,SUMIF('Calcul'!$B$2:$B$85,7,'Calcul'!$R$2:$R$85))*'Hypothèses'!$C$54)/('Hypothèses'!$C$55+(1-'Hypothèses'!$C$56)*((SUMIF('Calcul'!$B$2:$B$85,1,'Calcul'!$R$2:$R$85)-MAX(0,SUMIF('Calcul'!$B$2:$B$85,1,'Calcul'!$R$2:$R$85))*'Hypothèses'!$C$54)+(SUMIF('Calcul'!$B$2:$B$85,2,'Calcul'!$R$2:$R$85)-MAX(0,SUMIF('Calcul'!$B$2:$B$85,2,'Calcul'!$R$2:$R$85))*'Hypothèses'!$C$54)+(SUMIF('Calcul'!$B$2:$B$85,3,'Calcul'!$R$2:$R$85)-MAX(0,SUMIF('Calcul'!$B$2:$B$85,3,'Calcul'!$R$2:$R$85))*'Hypothèses'!$C$54)+(SUMIF('Calcul'!$B$2:$B$85,4,'Calcul'!$R$2:$R$85)-MAX(0,SUMIF('Calcul'!$B$2:$B$85,4,'Calcul'!$R$2:$R$85))*'Hypothèses'!$C$54)+(SUMIF('Calcul'!$B$2:$B$85,5,'Calcul'!$R$2:$R$85)-MAX(0,SUMIF('Calcul'!$B$2:$B$85,5,'Calcul'!$R$2:$R$85))*'Hypothèses'!$C$54)+(SUMIF('Calcul'!$B$2:$B$85,6,'Calcul'!$R$2:$R$85)-MAX(0,SUMIF('Calcul'!$B$2:$B$85,6,'Calcul'!$R$2:$R$85))*'Hypothèses'!$C$54)+(SUMIF('Calcul'!$B$2:$B$85,7,'Calcul'!$R$2:$R$85)-MAX(0,SUMIF('Calcul'!$B$2:$B$85,7,'Calcul'!$R$2:$R$85))*'Hypothèses'!$C$54)))
B25: Rentabilité du capital social | C25: =(SUMIF('Calcul'!$B$2:$B$85,1,'Calcul'!$R$2:$R$85)-MAX(0,SUMIF('Calcul'!$B$2:$B$85,1,'Calcul'!$R$2:$R$85))*'Hypothèses'!$C$54)/'Hypothèses'!$C$55 | D25: =(SUMIF('Calcul'!$B$2:$B$85,2,'Calcul'!$R$2:$R$85)-MAX(0,SUMIF('Calcul'!$B$2:$B$85,2,'Calcul'!$R$2:$R$85))*'Hypothèses'!$C$54)/'Hypothèses'!$C$55 | E25: =(SUMIF('Calcul'!$B$2:$B$85,3,'Calcul'!$R$2:$R$85)-MAX(0,SUMIF('Calcul'!$B$2:$B$85,3,'Calcul'!$R$2:$R$85))*'Hypothèses'!$C$54)/'Hypothèses'!$C$55 | F25: =(SUMIF('Calcul'!$B$2:$B$85,4,'Calcul'!$R$2:$R$85)-MAX(0,SUMIF('Calcul'!$B$2:$B$85,4,'Calcul'!$R$2:$R$85))*'Hypothèses'!$C$54)/'Hypothèses'!$C$55 | G25: =(SUMIF('Calcul'!$B$2:$B$85,5,'Calcul'!$R$2:$R$85)-MAX(0,SUMIF('Calcul'!$B$2:$B$85,5,'Calcul'!$R$2:$R$85))*'Hypothèses'!$C$54)/'Hypothèses'!$C$55 | H25: =(SUMIF('Calcul'!$B$2:$B$85,6,'Calcul'!$R$2:$R$85)-MAX(0,SUMIF('Calcul'!$B$2:$B$85,6,'Calcul'!$R$2:$R$85))*'Hypothèses'!$C$54)/'Hypothèses'!$C$55 | I25: =(SUMIF('Calcul'!$B$2:$B$85,7,'Calcul'!$R$2:$R$85)-MAX(0,SUMIF('Calcul'!$B$2:$B$85,7,'Calcul'!$R$2:$R$85))*'Hypothèses'!$C$54)/'Hypothèses'!$C$55

Sheet Capacité leasing
B1: Capacité de remboursement du leasing
B2: L'indicateur clé pour le bailleur : les loyers sont couverts plusieurs fois par les flux d'exploitation.
B4: AU NIVEAU D'UNE MACHINE (An 1)
B5: Revenu HCTECH / machine / an (part 60 %) | C5: ='Hypothèses'!$C$19*365*'Hypothèses'!$C$20*'Hypothèses'!$C$22
B6: Loyer de leasing / machine / an | C6: ='Hypothèses'!$C$13
B7: Couverture du loyer par le revenu | C7: =C5/C6 | D7: → chaque machine couvre largement son propre loyer
B9: AU NIVEAU DE LA SOCIÉTÉ (par année)
C10: An 1 | D10: An 2 | E10: An 3 | F10: An 4 | G10: An 5 | H10: An 6 | I10: An 7 | J10: Total 7 ans
B11: Loyers leasing machines | C11: =SUMIF('Calcul'!$B$2:$B$85,1,'Calcul'!$J$2:$J$85) | D11: =SUMIF('Calcul'!$B$2:$B$85,2,'Calcul'!$J$2:$J$85) | E11: =SUMIF('Calcul'!$B$2:$B$85,3,'Calcul'!$J$2:$J$85) | F11: =SUMIF('Calcul'!$B$2:$B$85,4,'Calcul'!$J$2:$J$85) | G11: =SUMIF('Calcul'!$B$2:$B$85,5,'Calcul'!$J$2:$J$85) | H11: =SUMIF('Calcul'!$B$2:$B$85,6,'Calcul'!$J$2:$J$85) | I11: =SUMIF('Calcul'!$B$2:$B$85,7,'Calcul'!$J$2:$J$85) | J11: =SUM(C11:I11)
B12: Loyer leasing véhicule | C12: =SUMIF('Calcul'!$B$2:$B$85,1,'Calcul'!$Q$2:$Q$85) | D12: =SUMIF('Calcul'!$B$2:$B$85,2,'Calcul'!$Q$2:$Q$85) | E12: =SUMIF('Calcul'!$B$2:$B$85,3,'Calcul'!$Q$2:$Q$85) | F12: =SUMIF('Calcul'!$B$2:$B$85,4,'Calcul'!$Q$2:$Q$85) | G12: =SUMIF('Calcul'!$B$2:$B$85,5,'Calcul'!$Q$2:$Q$85) | H12: =SUMIF('Calcul'!$B$2:$B$85,6,'Calcul'!$Q$2:$Q$85) | I12: =SUMIF('Calcul'!$B$2:$B$85,7,'Calcul'!$Q$2:$Q$85) | J12: =SUM(C12:I12)
B13: Total engagements leasing | C13: =SUMIF('Calcul'!$B$2:$B$85,1,'Calcul'!$J$2:$J$85)+SUMIF('Calcul'!$B$2:$B$85,1,'Calcul'!$Q$2:$Q$85) | D13: =SUMIF('Calcul'!$B$2:$B$85,2,'Calcul'!$J$2:$J$85)+SUMIF('Calcul'!$B$2:$B$85,2,'Calcul'!$Q$2:$Q$85) | E13: =SUMIF('Calcul'!$B$2:$B$85,3,'Calcul'!$J$2:$J$85)+SUMIF('Calcul'!$B$2:$B$85,3,'Calcul'!$Q$2:$Q$85) | F13: =SUMIF('Calcul'!$B$2:$B$85,4,'Calcul'!$J$2:$J$85)+SUMIF('Calcul'!$B$2:$B$85,4,'Calcul'!$Q$2:$Q$85) | G13: =SUMIF('Calcul'!$B$2:$B$85,5,'Calcul'!$J$2:$J$85)+SUMIF('Calcul'!$B$2:$B$85,5,'Calcul'!$Q$2:$Q$85) | H13: =SUMIF('Calcul'!$B$2:$B$85,6,'Calcul'!$J$2:$J$85)+SUMIF('Calcul'!$B$2:$B$85,6,'Calcul'!$Q$2:$Q$85) | I13: =SUMIF('Calcul'!$B$2:$B$85,7,'Calcul'!$J$2:$J$85)+SUMIF('Calcul'!$B$2:$B$85,7,'Calcul'!$Q$2:$Q$85) | J13: =SUM(C13:I13)
B14: EBITDA avant loyers de leasing | C14: =SUMIF('Calcul'!$B$2:$B$85,1,'Calcul'!$R$2:$R$85)+SUMIF('Calcul'!$B$2:$B$85,1,'Calcul'!$J$2:$J$85)+SUMIF('Calcul'!$B$2:$B$85,1,'Calcul'!$Q$2:$Q$85) | D14: =SUMIF('Calcul'!$B$2:$B$85,2,'Calcul'!$R$2:$R$85)+SUMIF('Calcul'!$B$2:$B$85,2,'Calcul'!$J$2:$J$85)+SUMIF('Calcul'!$B$2:$B$85,2,'Calcul'!$Q$2:$Q$85) | E14: =SUMIF('Calcul'!$B$2:$B$85,3,'Calcul'!$R$2:$R$85)+SUMIF('Calcul'!$B$2:$B$85,3,'Calcul'!$J$2:$J$85)+SUMIF('Calcul'!$B$2:$B$85,3,'Calcul'!$Q$2:$Q$85) | F14: =SUMIF('Calcul'!$B$2:$B$85,4,'Calcul'!$R$2:$R$85)+SUMIF('Calcul'!$B$2:$B$85,4,'Calcul'!$J$2:$J$85)+SUMIF('Calcul'!$B$2:$B$85,4,'Calcul'!$Q$2:$Q$85) | G14: =SUMIF('Calcul'!$B$2:$B$85,5,'Calcul'!$R$2:$R$85)+SUMIF('Calcul'!$B$2:$B$85,5,'Calcul'!$J$2:$J$85)+SUMIF('Calcul'!$B$2:$B$85,5,'Calcul'!$Q$2:$Q$85) | H14: =SUMIF('Calcul'!$B$2:$B$85,6,'Calcul'!$R$2:$R$85)+SUMIF('Calcul'!$B$2:$B$85,6,'Calcul'!$J$2:$J$85)+SUMIF('Calcul'!$B$2:$B$85,6,'Calcul'!$Q$2:$Q$85) | I14: =SUMIF('Calcul'!$B$2:$B$85,7,'Calcul'!$R$2:$R$85)+SUMIF('Calcul'!$B$2:$B$85,7,'Calcul'!$J$2:$J$85)+SUMIF('Calcul'!$B$2:$B$85,7,'Calcul'!$Q$2:$Q$85) | J14: =SUM(C14:I14)
B15: Couverture du service leasing (DSCR) | C15: =(SUMIF('Calcul'!$B$2:$B$85,1,'Calcul'!$R$2:$R$85)+SUMIF('Calcul'!$B$2:$B$85,1,'Calcul'!$J$2:$J$85)+SUMIF('Calcul'!$B$2:$B$85,1,'Calcul'!$Q$2:$Q$85))/(SUMIF('Calcul'!$B$2:$B$85,1,'Calcul'!$J$2:$J$85)+SUMIF('Calcul'!$B$2:$B$85,1,'Calcul'!$Q$2:$Q$85)) | D15: =(SUMIF('Calcul'!$B$2:$B$85,2,'Calcul'!$R$2:$R$85)+SUMIF('Calcul'!$B$2:$B$85,2,'Calcul'!$J$2:$J$85)+SUMIF('Calcul'!$B$2:$B$85,2,'Calcul'!$Q$2:$Q$85))/(SUMIF('Calcul'!$B$2:$B$85,2,'Calcul'!$J$2:$J$85)+SUMIF('Calcul'!$B$2:$B$85,2,'Calcul'!$Q$2:$Q$85)) | E15: =(SUMIF('Calcul'!$B$2:$B$85,3,'Calcul'!$R$2:$R$85)+SUMIF('Calcul'!$B$2:$B$85,3,'Calcul'!$J$2:$J$85)+SUMIF('Calcul'!$B$2:$B$85,3,'Calcul'!$Q$2:$Q$85))/(SUMIF('Calcul'!$B$2:$B$85,3,'Calcul'!$J$2:$J$85)+SUMIF('Calcul'!$B$2:$B$85,3,'Calcul'!$Q$2:$Q$85)) | F15: =(SUMIF('Calcul'!$B$2:$B$85,4,'Calcul'!$R$2:$R$85)+SUMIF('Calcul'!$B$2:$B$85,4,'Calcul'!$J$2:$J$85)+SUMIF('Calcul'!$B$2:$B$85,4,'Calcul'!$Q$2:$Q$85))/(SUMIF('Calcul'!$B$2:$B$85,4,'Calcul'!$J$2:$J$85)+SUMIF('Calcul'!$B$2:$B$85,4,'Calcul'!$Q$2:$Q$85)) | G15: =(SUMIF('Calcul'!$B$2:$B$85,5,'Calcul'!$R$2:$R$85)+SUMIF('Calcul'!$B$2:$B$85,5,'Calcul'!$J$2:$J$85)+SUMIF('Calcul'!$B$2:$B$85,5,'Calcul'!$Q$2:$Q$85))/(SUMIF('Calcul'!$B$2:$B$85,5,'Calcul'!$J$2:$J$85)+SUMIF('Calcul'!$B$2:$B$85,5,'Calcul'!$Q$2:$Q$85)) | H15: =(SUMIF('Calcul'!$B$2:$B$85,6,'Calcul'!$R$2:$R$85)+SUMIF('Calcul'!$B$2:$B$85,6,'Calcul'!$J$2:$J$85)+SUMIF('Calcul'!$B$2:$B$85,6,'Calcul'!$Q$2:$Q$85))/(SUMIF('Calcul'!$B$2:$B$85,6,'Calcul'!$J$2:$J$85)+SUMIF('Calcul'!$B$2:$B$85,6,'Calcul'!$Q$2:$Q$85)) | I15: =(SUMIF('Calcul'!$B$2:$B$85,7,'Calcul'!$R$2:$R$85)+SUMIF('Calcul'!$B$2:$B$85,7,'Calcul'!$J$2:$J$85)+SUMIF('Calcul'!$B$2:$B$85,7,'Calcul'!$Q$2:$Q$85))/(SUMIF('Calcul'!$B$2:$B$85,7,'Calcul'!$J$2:$J$85)+SUMIF('Calcul'!$B$2:$B$85,7,'Calcul'!$Q$2:$Q$85)) | J15: =AVERAGE(C15:I15)
B17: DSCR minimum sur la période | C17: =MIN(C15:I15) | D17: Un DSCR > 1 signifie que l'exploitation couvre intégralement le service du leasing chaque année.

Sheet Dividendes
B1: Distribution & actionnariat
B2: Priorité à l'investisseur (capital + prime 20 % = 360 k), puis pro-rata. 30 % conservé en réserve.
C4: An 1 | D4: An 2 | E4: An 3 | F4: An 4 | G4: An 5 | H4: An 6 | I4: An 7 | J4: Total 7 ans
