Workbook

Sheet Hypothèses
A1: Élément | B1: Valeur
A2: Capital social (TND) | B2: 500000
A3: Fonds de roulement (TND) | B3: 300000
A4: Répartition Actionnaires | B4: A1:32,5% - A2:32,5% - A3:20% - A4:15%
A5: Prix machine (USD) | B5: 17000 | E5: =B9*14 -> 755074.04 | F5: =E5*0.2 -> 151014.81 | G5: =E5-F5 -> 604059.23
A6: Taux de change | B6: 2.92
A7: Prix machine (TND) | B7: =B5*B6 -> 49640
A8: Frais import (2,5%) | B8: =B7*1.025 -> 50881 | C8: =B7*0.025 -> 1241 | D8: =C8*14 -> 17374
A9: TVA (6%) | B9: =B8*1.06 -> 53933.86
A10: Nombre de machines initial | B10: 54
A11: Frais installation (TND) | B11: 3500
A12: Mode financement | B12: Leasing
A13: Taux leasing | B13: 0.12
A14: Durée leasing | B14: 6 ans
A15: Année de grâce | B15: 1 an
A16: moyenne litres vendus par kiosque cible par jour | B16: 15000
A17: taux de récupération | B17: 0.004
A18: prix litre d'essence sans plomb (TND) | B18: 2.525
A19: futurs achats machines | B19: 14 tout les 4 mois à patir du mois 12
A20: règlement futurs machines par notre trésorerie (coût total 755 074,040 TND) | B20: 151 014,808 TND avance 20%
B21: 604 059,232 TND à m+9
A22: trésorerie de départ (TND) | B22: 300000

Sheet Revenus
A1: Mois | B1: Machines actives | C1: Revenu brut/machine (TND/mois) | D1: Revenu société 60%/machine | E1: Revenu total société (TND)
A2: 1 | B2: 0 | C2: =Hypothèses!$B$16*Hypothèses!$B$17*Hypothèses!$B$18*30 -> 4545 | D2: =C2*0.6 -> 2727 | E2: =D2*B2 -> 0
A3: 2 | B3: 0 | C3: =Hypothèses!$B$16*Hypothèses!$B$17*Hypothèses!$B$18*30 -> 4545 | D3: =C3*0.6 -> 2727 | E3: =D3*B3 -> 0
A4: 3 | B4: 14 | C4: =Hypothèses!$B$16*Hypothèses!$B$17*Hypothèses!$B$18*30 -> 4545 | D4: =C4*0.6 -> 2727 | E4: =D4*B4 -> 38178
A5: 4 | B5: 14 | C5: =Hypothèses!$B$16*Hypothèses!$B$17*Hypothèses!$B$18*30 -> 4545 | D5: =C5*0.6 -> 2727 | E5: =D5*B5 -> 38178
A6: 5 | B6: 14 | C6: =Hypothèses!$B$16*Hypothèses!$B$17*Hypothèses!$B$18*30 -> 4545 | D6: =C6*0.6 -> 2727 | E6: =D6*B6 -> 38178
A7: 6 | B7: 28 | C7: =Hypothèses!$B$16*Hypothèses!$B$17*Hypothèses!$B$18*30 -> 4545 | D7: =C7*0.6 -> 2727 | E7: =D7*B7 -> 76356
A8: 7 | B8: 28 | C8: =Hypothèses!$B$16*Hypothèses!$B$17*Hypothèses!$B$18*30 -> 4545 | D8: =C8*0.6 -> 2727 | E8: =D8*B8 -> 76356
A9: 8 | B9: 28 | C9: =Hypothèses!$B$16*Hypothèses!$B$17*Hypothèses!$B$18*30 -> 4545 | D9: =C9*0.6 -> 2727 | E9: =D9*B9 -> 76356
A10: 9 | B10: 42 | C10: =Hypothèses!$B$16*Hypothèses!$B$17*Hypothèses!$B$18*30 -> 4545 | D10: =C10*0.6 -> 2727 | E10: =D10*B10 -> 114534
A11: 10 | B11: 42 | C11: =Hypothèses!$B$16*Hypothèses!$B$17*Hypothèses!$B$18*30 -> 4545 | D11: =C11*0.6 -> 2727 | E11: =D11*B11 -> 114534
A12: 11 | B12: 42 | C12: =Hypothèses!$B$16*Hypothèses!$B$17*Hypothèses!$B$18*30 -> 4545 | D12: =C12*0.6 -> 2727 | E12: =D12*B12 -> 114534
A13: 12 | B13: 56 | C13: =Hypothèses!$B$16*Hypothèses!$B$17*Hypothèses!$B$18*30 -> 4545 | D13: =C13*0.6 -> 2727 | E13: =D13*B13 -> 152712
... A84: 83 | B84: 196 | C84: =Hypothèses!$B$16*Hypothèses!$B$17*Hypothèses!$B$18*30 -> 4545 | D84: =C84*0.6 -> 2727 | E84: =D84*B84 -> 534492

Sheet Charges
A1: Mois | B1: Salaires nets A3+A4 | C1: Charges sociales (30%) | D1: Salaires + charges | E1: Bonus A1+A2 | F1: Bureau | G1: Voiture | H1: Maintenance | I1: Installation | J1: Total charges (hors leasing)
A2: 1 | B2: 4000 | C2: =B2*0.3 -> 1200 | D2: =C2+B2 -> 5200 | E2: 0 | F2: 1500 | G2: 2000 | H2: =100*Revenus!B2 -> 0 | I2: 0 | J2: =D2+E2+F2+G2+H2+I2 -> 8700
A3: 2 | B3: 4000 | C3: =B3*0.3 -> 1200 | D3: =C3+B3 -> 5200 | E3: 0 | F3: 1500 | G3: 2000 | H3: =100*Revenus!B3 -> 0 | I3: =Hypothèses!$B$11*(Revenus!B4-Revenus!B3) -> 49000 | J3: =D3+E3+F3+G3+H3+I3 -> 57700
A4: 3 | B4: 4000 | C4: =B4*0.3 -> 1200 | D4: =C4+B4 -> 5200 | E4: 0 | F4: 1500 | G4: 2000 | H4: =100*Revenus!B4 -> 1400 | I4: =Hypothèses!$B$11*(Revenus!B5-Revenus!B4) -> 0 | J4: =D4+E4+F4+G4+H4+I4 -> 10100
A5: 4 | B5: 4000 | C5: =B5*0.3 -> 1200 | D5: =C5+B5 -> 5200 | E5: 0 | F5: 1500 | G5: 2000 | H5: =100*Revenus!B5 -> 1400 | I5: =Hypothèses!$B$11*(Revenus!B6-Revenus!B5) -> 0 | J5: =D5+E5+F5+G5+H5+I5 -> 10100
A6: 5 | B6: 4000 | C6: =B6*0.3 -> 1200 | D6: =C6+B6 -> 5200 | E6: 0 | F6: 1500 | G6: 2000 | H6: =100*Revenus!B6 -> 1400 | I6: =Hypothèses!$B$11*(Revenus!B7-Revenus!B6) -> 49000 | J6: =D6+E6+F6+G6+H6+I6 -> 59100
A7: 6 | B7: 4000 | C7: =B7*0.3 -> 1200 | D7: =C7+B7 -> 5200 | E7: 0 | F7: 1500 | G7: 2000 | H7: =100*Revenus!B7 -> 2800 | I7: =Hypothèses!$B$11*(Revenus!B8-Revenus!B7) -> 0 | J7: =D7+E7+F7+G7+H7+I7 -> 11500
A8: 7 | B8: 4000 | C8: =B8*0.3 -> 1200 | D8: =C8+B8 -> 5200 | E8: 0 | F8: 1500 | G8: 2000 | H8: =100*Revenus!B8 -> 2800 | I8: =Hypothèses!$B$11*(Revenus!B9-Revenus!B8) -> 0 | J8: =D8+E8+F8+G8+H8+I8 -> 11500
A9: 8 | B9: 4000 | C9: =B9*0.3 -> 1200 | D9: =C9+B9 -> 5200 | E9: 0 | F9: 1500 | G9: 2000 | H9: =100*Revenus!B9 -> 2800 | I9: =Hypothèses!$B$11*(Revenus!B10-Revenus!B9) -> 49000 | J9: =D9+E9+F9+G9+H9+I9 -> 60500
A10: 9 | B10: 4000 | C10: =B10*0.3 -> 1200 | D10: =C10+B10 -> 5200 | E10: 0 | F10: 1500 | G10: 2000 | H10: =100*Revenus!B10 -> 4200 | I10: =Hypothèses!$B$11*(Revenus!B11-Revenus!B10) -> 0 | J10: =D10+E10+F10+G10+H10+I10 -> 12900
A11: 10 | B11: 4000 | C11: =B11*0.3 -> 1200 | D11: =C11+B11 -> 5200 | E11: 0 | F11: 1500 | G11: 2000 | H11: =100*Revenus!B11 -> 4200 | I11: =Hypothèses!$B$11*(Revenus!B12-Revenus!B11) -> 0 | J11: =D11+E11+F11+G11+H11+I11 -> 12900
A12: 11 | B12: 4000 | C12: =B12*0.3 -> 1200 | D12: =C12+B12 -> 5200 | E12: 0 | F12: 1500 | G12: 2000 | H12: =100*Revenus!B12 -> 4200 | I12: =Hypothèses!$B$11*(Revenus!B13-Revenus!B12) -> 49000 | J12: =D12+E12+F12+G12+H12+I12 -> 61900
A13: 12 | B13: 4000 | C13: =B13*0.3 -> 1200 | D13: =C13+B13 -> 5200 | E13: 0 | F13: 1500 | G13: 2000 | H13: =100*Revenus!B13 -> 5600 | I13: =Hypothèses!$B$11*(Revenus!B14-Revenus!B13) -> 0 | J13: =D13+E13+F13+G13+H13+I13 -> 14300
A14: 13 | B14: 8000 | C14: =B14*0.3 -> 2400 | D14: =C14+B14 -> 10400 | E14: 0 | F14: 1500 | G14: 2000 | H14: =100*Revenus!B14 -> 5600 | I14: =Hypothèses!$B$11*(Revenus!B15-Revenus!B14) -> 0 | J14: =D14+E14+F14+G14+H14+I14 -> 19500
... A73: 72 | B73: 8000 | C73: =B73*0.3 -> 2400 | D73: =C73+B73 -> 10400 | E73: 100000 | F73: 1500 | G73: 2000 | H73: =100*Revenus!B73 -> 19600 | I73: =Hypothèses!$B$11*(Revenus!B74-Revenus!B73) -> 0 | J73: =D73+E73+F73+G73+H73+I73 -> 133500
A74: 73 | B74: 8000 | C74: =B74*0.3 -> 2400 | D74: =C74+B74 -> 10400 | F74: 1500 | G74: 2000 | H74: =100*Revenus!B74 -> 19600 | J74: =D74+E74+F74+G74+H74+I74 -> 33500
A75: 74 | B75: 8000 | C75: =B75*0.3 -> 2400 | D75: =C75+B75 -> 10400 | F75: 1500 | G75: 2000 | H75: =100*Revenus!B75 -> 19600 | J75: =D75+E75+F75+G75+H75+I75 -> 33500
A76: 75 | B76: 8000 | C76: =B76*0.3 -> 2400 | D76: =C76+B76 -> 10400 | F76: 1500 | G76: 2000 | H76: =100*Revenus!B76 -> 19600 | J76: =D76+E76+F76+G76+H76+I76 -> 33500
A77: 76 | B77: 8000 | C77: =B77*0.3 -> 2400 | D77: =C77+B77 -> 10400 | F77: 1500 | G77: 2000 | H77: =100*Revenus!B77 -> 19600 | J77: =D77+E77+F77+G77+H77+I77 -> 33500
A78: 77 | B78: 8000 | C78: =B78*0.3 -> 2400 | D78: =C78+B78 -> 10400 | F78: 1500 | G78: 2000 | H78: =100*Revenus!B78 -> 19600 | J78: =D78+E78+F78+G78+H78+I78 -> 33500
A79: 78 | B79: 8000 | C79: =B79*0.3 -> 2400 | D79: =C79+B79 -> 10400 | F79: 1500 | G79: 2000 | H79: =100*Revenus!B79 -> 19600 | J79: =D79+E79+F79+G79+H79+I79 -> 33500
A80: 79 | B80: 8000 | C80: =B80*0.3 -> 2400 | D80: =C80+B80 -> 10400 | F80: 1500 | G80: 2000 | H80: =100*Revenus!B80 -> 19600 | J80: =D80+E80+F80+G80+H80+I80 -> 33500
A81: 80 | B81: 8000 | C81: =B81*0.3 -> 2400 | D81: =C81+B81 -> 10400 | F81: 1500 | G81: 2000 | H81: =100*Revenus!B81 -> 19600 | J81: =D81+E81+F81+G81+H81+I81 -> 33500
A82: 81 | B82: 8000 | C82: =B82*0.3 -> 2400 | D82: =C82+B82 -> 10400 | F82: 1500 | G82: 2000 | H82: =100*Revenus!B82 -> 19600 | J82: =D82+E82+F82+G82+H82+I82 -> 33500
A83: 82 | B83: 8000 | C83: =B83*0.3 -> 2400 | D83: =C83+B83 -> 10400 | F83: 1500 | G83: 2000 | H83: =100*Revenus!B83 -> 19600 | J83: =D83+E83+F83+G83+H83+I83 -> 33500
A84: 83 | B84: 8000 | C84: =B84*0.3 -> 2400 | D84: =C84+B84 -> 10400 | F84: 1500 | G84: 2000 | H84: =100*Revenus!B84 -> 19600 | J84: =D84+E84+F84+G84+H84+I84 -> 33500

Sheet Leasing (2)
A1: Mois | B1: Mensualité totale | C1: Principal | D1: Interets | E1: Solde restant dû (fin de mois) | F1: Mensualité totale | G1: Principal | H1: Interets | I1: Solde restant dû (fin de mois) | J1: Mensualité totale | K1: Principal | L1: Interets | M1: Solde restant dû (fin de mois) | N1: charge leasing total
A2: 1 | B2: =C2+D2 -> 7550.7404 | D2: 7550.7404 | E2: 755074.04 | F2: =G2+H2 -> 0 | J2: =K2+L2 -> 0 | N2: =J2+F2+B2 -> 7550.7404
A3: 2 | B3: =C3+D3 -> 7550.7404 | D3: 7550.7404 | E3: 755074.04 | F3: =G3+H3 -> 0 | J3: =K3+L3 -> 0 | N3: =J3+F3+B3 -> 7550.7404
A4: 3 | B4: =C4+D4 -> 7550.7404 | D4: 7550.7404 | E4: 755074.04 | F4: =G4+H4 -> 0 | J4: =K4+L4 -> 0 | N4: =J4+F4+B4 -> 7550.7404
A5: 4 | B5: =C5+D5 -> 7550.7404 | D5: 7550.7404 | E5: 755074.04 | F5: =G5+H5 -> 7550.7404 | H5: 7550.7404 | I5: 755074.04 | J5: =K5+L5 -> 0 | N5: =J5+F5+B5 -> 15101.481
A6: 5 | B6: =C6+D6 -> 7550.7404 | D6: 7550.7404 | E6: 755074.04 | F6: =G6+H6 -> 7550.7404 | H6: 7550.7404 | I6: 755074.04 | J6: =K6+L6 -> 0 | N6: =J6+F6+B6 -> 15101.481
A7: 6 | B7: =C7+D7 -> 7550.7404 | D7: 7550.7404 | E7: 755074.04 | F7: =G7+H7 -> 7550.7404 | H7: 7550.7404 | I7: 755074.04 | J7: =K7+L7 -> 0 | N7: =J7+F7+B7 -> 15101.481
A8: 7 | B8: =C8+D8 -> 7550.7404 | D8: 7550.7404 | E8: 755074.04 | F8: =G8+H8 -> 7550.7404 | H8: 7550.7404 | I8: 755074.04 | J8: =K8+L8 -> 0 | N8: =J8+F8+B8 -> 15101.481
A9: 8 | B9: =C9+D9 -> 7550.7404 | D9: 7550.7404 | E9: 755074.04 | F9: =G9+H9 -> 7550.7404 | H9: 7550.7404 | I9: 755074.04 | J9: =K9+L9 -> 7550.7404 | L9: 7550.7404 | M9: 755074.04 | N9: =J9+F9+B9 -> 22652.221
A10: 9 | B10: =C10+D10 -> 7550.7404 | D10: 7550.7404 | E10: 755074.04 | F10: =G10+H10 -> 7550.7404 | H10: 7550.7404 | I10: 755074.04 | J10: =K10+L10 -> 7550.7404 | L10: 7550.7404 | M10: 755074.04 | N10: =J10+F10+B10 -> 22652.221
A11: 10 | B11: =C11+D11 -> 7550.7404 | D11: 7550.7404 | E11: 755074.04 | F11: =G11+H11 -> 7550.7404 | H11: 7550.7404 | I11: 755074.04 | J11: =K11+L11 -> 7550.7404 | L11: 7550.7404 | M11: 755074.04 | N11: =J11+F11+B11 -> 22652.221
A12: 11 | B12: =C12+D12 -> 7550.7404 | D12: 7550.7404 | E12: 755074.04 | F12: =G12+H12 -> 7550.7404 | H12: 7550.7404 | I12: 755074.04 | J12: =K12+L12 -> 7550.7404 | L12: 7550.7404 | M12: 755074.04 | N12: =J12+F12+B12 -> 22652.221
A13: 12 | B13: =C13+D13 -> 7550.7404 | D13: 7550.7404 | E13: 755074.04 | F13: =G13+H13 -> 7550.7404 | H13: 7550.7404 | I13: 755074.04 | J13: =K13+L13 -> 7550.7404 | L13: 7550.7404 | M13: 755074.04 | N13: =J13+F13+B13 -> 22652.221
A14: 13 | B14: =C14+D14 -> 16796.205 | C14: 9245.4646 | D14: 7550.7404 | E14: =E13-C14 -> 745828.58 | F14: =G14+H14 -> 7550.7404 | H14: 7550.7404 | I14: 755074.04 | J14: =K14+L14 -> 7550.7404 | L14: 7550.7404 | M14: 755074.04 | N14: =J14+F14+B14 -> 31897.686
A15: 14 | B15: =C15+D15 -> 16796.205 | C15: 9337.9192 | D15: 7458.2858 | E15: =E14-C15 -> 736490.66 | F15: =G15+H15 -> 7550.7404 | H15: 7550.7404 | I15: 755074.04 | J15: =K15+L15 -> 7550.7404 | L15: 7550.7404 | M15: 755074.04 | N15: =J15+F15+B15 -> 31897.686
A16: 15 | B16: =C16+D16 -> 16796.205 | C16: 9431.2984 | D16: 7364.9066 | E16: =E15-C16 -> 727059.36 | F16: =G16+H16 -> 7550.7404 | H16: 7550.7404 | I16: 755074.04 | J16: =K16+L16 -> 7550.7404 | L16: 7550.7404 | M16: 755074.04 | N16: =J16+F16+B16 -> 31897.686
A17: 16 | B17: =C17+D17 -> 16796.205 | C17: 9525.6114 | D17: 7270.5936 | E17: =E16-C17 -> 717533.75 | F17: =G17+H17 -> 16796.205 | G17: 9245.4646 | H17: 7550.7404 | I17: =I16-G17 -> 745828.58 | J17: =K17+L17 -> 7550.7404 | L17: 7550.7404 | M17: 755074.04 | N17: =J17+F17+B17 -> 41143.15
A18: 17 | B18: =C18+D18 -> 16796.205 | C18: 9620.8675 | D18: 7175.3375 | E18: =E17-C18 -> 707912.88 | F18: =G18+H18 -> 16796.205 | G18: 9337.9192 | H18: 7458.2858 | I18: =I17-G18 -> 736490.66 | J18: =K18+L18 -> 7550.7404 | L18: 7550.7404 | M18: 755074.04 | N18: =J18+F18+B18 -> 41143.15
A19: 18 | B19: =C19+D19 -> 16796.205 | C19: 9717.0762 | D19: 7079.1288 | E19: =E18-C19 -> 698195.8 | F19: =G19+H19 -> 16796.205 | G19: 9431.2984 | H19: 7364.9066 | I19: =I18-G19 -> 727059.36 | J19: =K19+L19 -> 7550.7404 | L19: 7550.7404 | M19: 755074.04 | N19: =J19+F19+B19 -> 41143.15
A20: 19 | B20: =C20+D20 -> 16796.205 | C20: 9814.247 | D20: 6981.958 | E20: =E19-C20 -> 688381.56 | F20: =G20+H20 -> 16796.205 | G20: 9525.6114 | H20: 7270.5936 | I20: =I19-G20 -> 717533.75 | J20: =K20+L20 -> 7550.7404 | L20: 7550.7404 | M20: 755074.04 | N20: =J20+F20+B20 -> 41143.15
A21: 20 | B21: =C21+D21 -> 16796.205 | C21: 9912.3894 | D21: 6883.8156 | E21: =E20-C21 -> 678469.17 | F21: =G21+H21 -> 16796.205 | G21: 9620.8675 | H21: 7175.3375 | I21: =I20-G21 -> 707912.88 | J21: =K21+L21 -> 16796.205 | K21: 9245.4646 | L21: 7550.7404 | M21: =M20-K21 -> 745828.58 | N21: =J21+F21+B21 -> 50388.615
A22: 21 | B22: =C22+D22 -> 16796.205 | C22: 10011.513 | D22: 6784.6917 | E22: =E21-C22 -> 668457.65 | F22: =G22+H22 -> 16796.205 | G22: 9717.0762 | H22: 7079.1288 | I22: =I21-G22 -> 698195.8 | J22: =K22+L22 -> 16796.205 | K22: 9337.9192 | L22: 7458.2858 | M22: =M21-K22 -> 736490.66 | N22: =J22+F22+B22 -> 50388.615
A23: 22 | B23: =C23+D23 -> 16796.205 | C23: 10111.628 | D23: 6684.5765 | E23: =E22-C23 -> 658346.02 | F23: =G23+H23 -> 16796.205 | G23: 9814.247 | H23: 6981.958 | I23: =I22-G23 -> 688381.56 | J23: =K23+L23 -> 16796.205 | K23: 9431.2984 | L23: 7364.9066 | M23: =M22-K23 -> 727059.36 | N23: =J23+F23+B23 -> 50388.615
A24: 23 | B24: =C24+D24 -> 16796.205 | C24: 10212.745 | D24: 6583.4602 | E24: =E23-C24 -> 648133.28 | F24: =G24+H24 -> 16796.205 | G24: 9912.3894 | H24: 6883.8156 | I24: =I23-G24 -> 678469.17 | J24: =K24+L24 -> 16796.205 | K24: 9525.6114 | L24: 7270.5936 | M24: =M23-K24 -> 717533.75 | N24: =J24+F24+B24 -> 50388.615
A25: 24 | B25: =C25+D25 -> 16796.205 | C25: 10314.872 | D25: 6481.3328 | E25: =E24-C25 -> 637818.41 | F25: =G25+H25 -> 16796.205 | G25: 10011.513 | H25: 6784.6917 | I25: =I24-G25 -> 668457.65 | J25: =K25+L25 -> 16796.205 | K25: 9620.8675 | L25: 7175.3375 | M25: =M24-K25 -> 707912.88 | N25: =J25+F25+B25 -> 50388.615
A26: 25 | B26: =C26+D26 -> 16796.205 | C26: 10418.021 | D26: 6378.1841 | E26: =E25-C26 -> 627400.39 | F26: =G26+H26 -> 16796.205 | G26: 10111.628 | H26: 6684.5765 | I26: =I25-G26 -> 658346.02 | J26: =K26+L26 -> 16796.205 | K26: 9717.0762 | L26: 7079.1288 | M26: =M25-K26 -> 698195.8 | N26: =J26+F26+B26 -> 50388.615
A27: 26 | B27: =C27+D27 -> 16796.205 | C27: 10522.201 | D27: 6274.0039 | E27: =E26-C27 -> 616878.19 | F27: =G27+H27 -> 16796.205 | G27: 10212.745 | H27: 6583.4602 | I27: =I26-G27 -> 648133.28 | J27: =K27+L27 -> 16796.205 | K27: 9814.247 | L27: 6981.958 | M27: =M26-K27 -> 688381.56 | N27: =J27+F27+B27 -> 50388.615
A28: 27 | B28: =C28+D28 -> 16796.205 | C28: 10627.423 | D28: 6168.7819 | E28: =E27-C28 -> 606250.76 | F28: =G28+H28 -> 16796.205 | G28: 10314.872 | H28: 6481.3328 | I28: =I27-G28 -> 637818.41 | J28: =K28+L28 -> 16796.205 | K28: 9912.3894 | L28: 6883.8156 | M28: =M27-K28 -> 678469.17 | N28: =J28+F28+B28 -> 50388.615
A29: 28 | B29: =C29+D29 -> 16796.205 | C29: 10733.697 | D29: 6062.5076 | E29: =E28-C29 -> 595517.07 | F29: =G29+H29 -> 16796.205 | G29: 10418.021 | H29: 6378.1841 | I29: =I28-G29 -> 627400.39 | J29: =K29+L29 -> 16796.205 | K29: 10011.513 | L29: 6784.6917 | M29: =M28-K29 -> 668457.65 | N29: =J29+F29+B29 -> 50388.615
A30: 29 | B30: =C30+D30 -> 16796.205 | C30: 10841.034 | D30: 5955.1707 | E30: =E29-C30 -> 584676.03 | F30: =G30+H30 -> 16796.205 | G30: 10522.201 | H30: 6274.0039 | I30: =I29-G30 -> 616878.19 | J30: =K30+L30 -> 16796.205 | K30: 10111.628 | L30: 6684.5765 | M30: =M29-K30 -> 658346.02 | N30: =J30+F30+B30 -> 50388.615
A31: 30 | B31: =C31+D31 -> 16796.205 | C31: 10949.445 | D31: 5846.7603 | E31: =E30-C31 -> 573726.59 | F31: =G31+H31 -> 16796.205 | G31: 10627.423 | H31: 6168.7819 | I31: =I30-G31 -> 606250.76 | J31: =K31+L31 -> 16796.205 | K31: 10212.745 | L31: 6583.4602 | M31: =M30-K31 -> 648133.28 | N31: =J31+F31+B31 -> 50388.615
A32: 31 | B32: =C32+D32 -> 16796.205 | C32: 11058.939 | D32: 5737.2659 | E32: =E31-C32 -> 562667.65 | F32: =G32+H32 -> 16796.205 | G32: 10733.697 | H32: 6062.5076 | I32: =I31-G32 -> 595517.07 | J32: =K32+L32 -> 16796.205 | K32: 10314.872 | L32: 6481.3328 | M32: =M31-K32 -> 637818.41 | N32: =J32+F32+B32 -> 50388.615
... A73: 72 | B73: =C73+D73 -> 16796.205 | C73: 16629.906 | D73: 166.29906 | E73: =E72-C73 -> 1.1168595e-09 | F73: =G73+H73 -> 16796.205 | G73: 16140.823 | H73: 655.38213 | I73: =I72-G73 -> 49397.39 | J73: =K73+L73 -> 16796.205 | K73: 15511.014 | L73: 1285.1915 | M73: =M72-K73 -> 113008.13 | N73: =J73+F73+B73 -> 50388.615
F74: =G74+H74 -> 16796.205 | G74: 16302.231 | H74: 493.9739 | I74: =I73-G74 -> 33095.159 | J74: =K74+L74 -> 16796.205 | K74: 15666.124 | L74: 1130.0813 | M74: =M73-K74 -> 97342.011 | N74: =J74+F74+B74 -> 33592.41
F75: =G75+H75 -> 16796.205 | G75: 16465.253 | H75: 330.95159 | I75: =I74-G75 -> 16629.906 | J75: =K75+L75 -> 16796.205 | K75: 15822.785 | L75: 973.42011 | M75: =M74-K75 -> 81519.226 | N75: =J75+F75+B75 -> 33592.41
F76: =G76+H76 -> 16796.205 | G76: 16629.906 | H76: 166.29906 | I76: =I75-G76 -> 1.1168595e-09 | J76: =K76+L76 -> 16796.205 | K76: 15981.013 | L76: 815.19226 | M76: =M75-K76 -> 65538.213 | N76: =J76+F76+B76 -> 33592.41
J77: =K77+L77 -> 16796.205 | K77: 16140.823 | L77: 655.38213 | M77: =M76-K77 -> 49397.39 | N77: =J77+F77+B77 -> 16796.205
J78: =K78+L78 -> 16796.205 | K78: 16302.231 | L78: 493.9739 | M78: =M77-K78 -> 33095.159 | N78: =J78+F78+B78 -> 16796.205
J79: =K79+L79 -> 16796.205 | K79: 16465.253 | L79: 330.95159 | M79: =M78-K79 -> 16629.906 | N79: =J79+F79+B79 -> 16796.205
J80: =K80+L80 -> 16796.205 | K80: 16629.906 | L80: 166.29906 | M80: =M79-K80 -> 1.1168595e-09 | N80: =J80+F80+B80 -> 16796.205

Sheet Cash-Flow
A1: Mois | B1: Entrées de trésorerie (Revenus) | C1: Sorties de trésorerie (Charges + Leasing + achat machines) | D1: Flux de trésorerie net | E1: Solde cumulé | F1: avance 20% | G1: reliquat 80%
A2: 1 | B2: =Revenus!E2 -> 0 | C2: =Charges!J2+'Leasing (2)'!N2+F2+G2 -> 16250.74 | D2: =B2-C2 -> -16250.74 | E2: =300000+D2 -> 283749.26
A3: 2 | B3: =Revenus!E3 -> 0 | C3: =Charges!J3+'Leasing (2)'!N3+F3+G3 -> 65250.74 | D3: =B3-C3 -> -65250.74 | E3: =E2+D3 -> 218498.52
A4: 3 | B4: =Revenus!E4 -> 38178 | C4: =Charges!J4+'Leasing (2)'!N4+F4+G4 -> 17650.74 | D4: =B4-C4 -> 20527.26 | E4: =E3+D4 -> 239025.78
A5: 4 | B5: =Revenus!E5 -> 38178 | C5: =Charges!J5+'Leasing (2)'!N5+F5+G5 -> 25201.481 | D5: =B5-C5 -> 12976.519 | E5: =E4+D5 -> 252002.3
A6: 5 | B6: =Revenus!E6 -> 38178 | C6: =Charges!J6+'Leasing (2)'!N6+F6+G6 -> 74201.481 | D6: =B6-C6 -> -36023.481 | E6: =E5+D6 -> 215978.82
A7: 6 | B7: =Revenus!E7 -> 76356 | C7: =Charges!J7+'Leasing (2)'!N7+F7+G7 -> 26601.481 | D7: =B7-C7 -> 49754.519 | E7: =E6+D7 -> 265733.34
A8: 7 | B8: =Revenus!E8 -> 76356 | C8: =Charges!J8+'Leasing (2)'!N8+F8+G8 -> 26601.481 | D8: =B8-C8 -> 49754.519 | E8: =E7+D8 -> 315487.86
A9: 8 | B9: =Revenus!E9 -> 76356 | C9: =Charges!J9+'Leasing (2)'!N9+F9+G9 -> 83152.221 | D9: =B9-C9 -> -6796.2212 | E9: =E8+D9 -> 308691.63
A10: 9 | B10: =Revenus!E10 -> 114534 | C10: =Charges!J10+'Leasing (2)'!N10+F10+G10 -> 35552.221 | D10: =B10-C10 -> 78981.779 | E10: =E9+D10 -> 387673.41
A11: 10 | B11: =Revenus!E11 -> 114534 | C11: =Charges!J11+'Leasing (2)'!N11+F11+G11 -> 186567.03 | D11: =B11-C11 -> -72033.029 | E11: =E10+D11 -> 315640.38 | F11: 151014.81
A12: 11 | B12: =Revenus!E12 -> 114534 | C12: =Charges!J12+'Leasing (2)'!N12+F12+G12 -> 84552.221 | D12: =B12-C12 -> 29981.779 | E12: =E11+D12 -> 345622.16
A13: 12 | B13: =Revenus!E13 -> 152712 | C13: =Charges!J13+'Leasing (2)'!N13+F13+G13 -> 36952.221 | D13: =B13-C13 -> 115759.78 | E13: =E12+D13 -> 461381.94
A14: 13 | B14: =Revenus!E14 -> 152712 | C14: =Charges!J14+'Leasing (2)'!N14+F14+G14 -> 51397.686 | D14: =B14-C14 -> 101314.31 | E14: =E13+D14 -> 562696.26
A15: 14 | B15: =Revenus!E15 -> 152712 | C15: =Charges!J15+'Leasing (2)'!N15+F15+G15 -> 202412.49 | D15: =B15-C15 -> -49700.494 | E15: =E14+D15 -> 512995.76 | F15: 151014.81
A16: 15 | B16: =Revenus!E16 -> 152712 | C16: =Charges!J16+'Leasing (2)'!N16+F16+G16 -> 100397.69 | D16: =B16-C16 -> 52314.314 | E16: =E15+D16 -> 565310.08
A17: 16 | B17: =Revenus!E17 -> 190890 | C17: =Charges!J17+'Leasing (2)'!N17+F17+G17 -> 62043.15 | D17: =B17-C17 -> 128846.85 | E17: =E16+D17 -> 694156.93
A18: 17 | B18: =Revenus!E18 -> 190890 | C18: =Charges!J18+'Leasing (2)'!N18+F18+G18 -> 62043.15 | D18: =B18-C18 -> 128846.85 | E18: =E17+D18 -> 823003.78
A19: 18 | B19: =Revenus!E19 -> 190890 | C19: =Charges!J19+'Leasing (2)'!N19+F19+G19 -> 213057.96 | D19: =B19-C19 -> -22167.958 | E19: =E18+D19 -> 800835.82 | F19: 151014.81
A20: 19 | B20: =Revenus!E20 -> 190890 | C20: =Charges!J20+'Leasing (2)'!N20+F20+G20 -> 715102.38 | D20: =B20-C20 -> -524212.38 | E20: =E19+D20 -> 276623.43 | G20: 604059.23
A21: 20 | B21: =Revenus!E21 -> 229068 | C21: =Charges!J21+'Leasing (2)'!N21+F21+G21 -> 72688.615 | D21: =B21-C21 -> 156379.39 | E21: =E20+D21 -> 433002.82
A22: 21 | B22: =Revenus!E22 -> 229068 | C22: =Charges!J22+'Leasing (2)'!N22+F22+G22 -> 72688.615 | D22: =B22-C22 -> 156379.39 | E22: =E21+D22 -> 589382.2
A23: 22 | B23: =Revenus!E23 -> 229068 | C23: =Charges!J23+'Leasing (2)'!N23+F23+G23 -> 223703.42 | D23: =B23-C23 -> 5364.5771 | E23: =E22+D23 -> 594746.78 | F23: 151014.81
A24: 23 | B24: =Revenus!E24 -> 229068 | C24: =Charges!J24+'Leasing (2)'!N24+F24+G24 -> 725747.85 | D24: =B24-C24 -> -496679.85 | E24: =E23+D24 -> 98066.935 | G24: 604059.23
A25: 24 | B25: =Revenus!E25 -> 267246 | C25: =Charges!J25+'Leasing (2)'!N25+F25+G25 -> 174088.61 | D25: =B25-C25 -> 93157.385 | E25: =E24+D25 -> 191224.32
A26: 25 | B26: =Revenus!E26 -> 267246 | C26: =Charges!J26+'Leasing (2)'!N26+F26+G26 -> 74088.615 | D26: =B26-C26 -> 193157.39 | E26: =E25+D26 -> 384381.71
A27: 26 | B27: =Revenus!E27 -> 267246 | C27: =Charges!J27+'Leasing (2)'!N27+F27+G27 -> 225103.42 | D27: =B27-C27 -> 42142.577 | E27: =E26+D27 -> 426524.28 | F27: 151014.81
A28: 27 | B28: =Revenus!E28 -> 267246 | C28: =Charges!J28+'Leasing (2)'!N28+F28+G28 -> 727147.85 | D28: =B28-C28 -> -459901.85 | E28: =E27+D28 -> -33377.565 | G28: 604059.23
A29: 28 | B29: =Revenus!E29 -> 305424 | C29: =Charges!J29+'Leasing (2)'!N29+F29+G29 -> 75488.615 | D29: =B29-C29 -> 229935.39 | E29: =E28+D29 -> 196557.82
A30: 29 | B30: =Revenus!E30 -> 305424 | C30: =Charges!J30+'Leasing (2)'!N30+F30+G30 -> 75488.615 | D30: =B30-C30 -> 229935.39 | E30: =E29+D30 -> 426493.21
A31: 30 | B31: =Revenus!E31 -> 305424 | C31: =Charges!J31+'Leasing (2)'!N31+F31+G31 -> 226503.42 | D31: =B31-C31 -> 78920.577 | E31: =E30+D31 -> 505413.78 | F31: 151014.81
A32: 31 | B32: =Revenus!E32 -> 305424 | C32: =Charges!J32+'Leasing (2)'!N32+F32+G32 -> 728547.85 | D32: =B32-C32 -> -423123.85 | E32: =E31+D32 -> 82289.935 | G32: 604059.23
A33: 32 | B33: =Revenus!E33 -> 343602 | C33: =Charges!J33+'Leasing (2)'!N33+F33+G33 -> 76888.615 | D33: =B33-C33 -> 266713.39 | E33: =E32+D33 -> 349003.32
A34: 33 | B34: =Revenus!E34 -> 343602 | C34: =Charges!J34+'Leasing (2)'!N34+F34+G34 -> 76888.615 | D34: =B34-C34 -> 266713.39 | E34: =E33+D34 -> 615716.71
A35: 34 | B35: =Revenus!E35 -> 343602 | C35: =Charges!J35+'Leasing (2)'!N35+F35+G35 -> 227903.42 | D35: =B35-C35 -> 115698.58 | E35: =E34+D35 -> 731415.28 | F35: 151014.81
A36: 35 | B36: =Revenus!E36 -> 343602 | C36: =Charges!J36+'Leasing (2)'!N36+F36+G36 -> 729947.85 | D36: =B36-C36 -> -386345.85 | E36: =E35+D36 -> 345069.44 | G36: 604059.23
A37: 36 | B37: =Revenus!E37 -> 381780 | C37: =Charges!J37+'Leasing (2)'!N37+F37+G37 -> 178288.61 | D37: =B37-C37 -> 203491.39 | E37: =E36+D37 -> 548560.82
A38: 37 | B38: =Revenus!E38 -> 381780 | C38: =Charges!J38+'Leasing (2)'!N38+F38+G38 -> 78288.615 | D38: =B38-C38 -> 303491.39 | E38: =E37+D38 -> 852052.21
A39: 38 | B39: =Revenus!E39 -> 381780 | C39: =Charges!J39+'Leasing (2)'!N39+F39+G39 -> 229303.42 | D39: =B39-C39 -> 152476.58 | E39: =E38+D39 -> 1004528.8 | F39: 151014.81
A40: 39 | B40: =Revenus!E40 -> 381780 | C40: =Charges!J40+'Leasing (2)'!N40+F40+G40 -> 731347.85 | D40: =B40-C40 -> -349567.85 | E40: =E39+D40 -> 654960.94 | G40: 604059.23
...

Sheet Leasing
A1: Mois | B1: Mensualité totale | C1: Principal | D1: Interets | E1: Solde restant dû (fin de mois)
A2: 1 | B2: 22099.73 | D2: 22099.73 | E2: 2651967.4
A3: 2 | B3: 22099.73 | D3: 22099.73 | E3: 2651967.4
A4: 3 | B4: 22099.73 | D4: 22099.73 | E4: 2651967.4
A5: 4 | B5: 22099.73 | D5: 22099.73 | E5: 2651967.4
A6: 5 | B6: 22099.73 | D6: 22099.73 | E6: 2651967.4
A7: 6 | B7: 22099.73 | D7: 22099.73 | E7: 2651967.4
A8: 7 | B8: 22099.73 | D8: 22099.73 | E8: 2651967.4
A9: 8 | B9: 22099.73 | D9: 22099.73 | E9: 2651967.4
A10: 9 | B10: 22099.73 | D10: 22099.73 | E10: 2651967.4
A11: 10 | B11: 22099.73 | D11: 22099.73 | E11: 2651967.4
A12: 11 | B12: 22099.73 | D12: 22099.73 | E12: 2651967.4
A13: 12 | B13: 22099.73 | D13: 22099.73 | E13: 2651967.4
A14: 13 | B14: =C14+D14 -> 56346.469 | C14: 34246.741 | D14: 22099.728 | E14: =E13-C14 -> 2617720.6
A15: 14 | B15: =C15+D15 -> 56346.469 | C15: 34532.131 | D15: 21814.338 | E15: =E14-C15 -> 2583188.5
A16: 15 | B16: =C16+D16 -> 56346.469 | C16: 34819.898 | D16: 21526.571 | E16: =E15-C16 -> 2548368.6
A17: 16 | B17: =C17+D17 -> 56346.469 | C17: 35110.064 | D17: 21236.405 | E17: =E16-C17 -> 2513258.5
A18: 17 | B18: =C18+D18 -> 56346.469 | C18: 35402.648 | D18: 20943.821 | E18: =E17-C18 -> 2477855.9
A19: 18 | B19: =C19+D19 -> 56346.469 | C19: 35697.67 | D19: 20648.799 | E19: =E18-C19 -> 2442158.2
A20: 19 | B20: =C20+D20 -> 56346.469 | C20: 35995.151 | D20: 20351.318 | E20: =E19-C20 -> 2406163.1
A21: 20 | B21: =C21+D21 -> 56346.469 | C21: 36295.11 | D21: 20051.359 | E21: =E20-C21 -> 2369867.9
A22: 21 | B22: =C22+D22 -> 56346.469 | C22: 36597.57 | D22: 19748.9 | E22: =E21-C22 -> 2333270.4
A23: 22 | B23: =C23+D23 -> 56346.469 | C23: 36902.549 | D23: 19443.92 | E23: =E22-C23 -> 2296367.8
A24: 23 | B24: =C24+D24 -> 56346.469 | C24: 37210.071 | D24: 19136.399 | E24: =E23-C24 -> 2259157.8
A25: 24 | B25: =C25+D25 -> 56346.469 | C25: 37520.154 | D25: 18826.315 | E25: =E24-C25 -> 2221637.6
... A73: 72 | B73: =C73+D73 -> 56346.469 | C73: 55880.796 | D73: 465.6733 | E73: =E72-C73 -> -1.4493708e-08

Sheet Résultats
A1: Mois | B1: Revenus | C1: Charges (hors leasing) | D1: Intérêts leasing | E1: Principal leasing | F1: Résultat net
A2: 1 | B2: =Revenus!E2 -> 0 | C2: =Charges!J2 -> 8700 | D2: =Leasing!D2 -> 22099.73 | E2: =Leasing!C2 -> 0 | F2: =B2-C2-D2-E2 -> -30799.73
A3: 2 | B3: =Revenus!E3 -> 0 | C3: =Charges!J3 -> 57700 | D3: =Leasing!D3 -> 22099.73 | E3: =Leasing!C3 -> 0 | F3: =B3-C3-D3-E3 -> -79799.73
A4: 3 | B4: =Revenus!E4 -> 38178 | C4: =Charges!J4 -> 10100 | D4: =Leasing!D4 -> 22099.73 | E4: =Leasing!C4 -> 0 | F4: =B4-C4-D4-E4 -> 5978.27
A5: 4 | B5: =Revenus!E5 -> 38178 | C5: =Charges!J5 -> 10100 | D5: =Leasing!D5 -> 22099.73 | E5: =Leasing!C5 -> 0 | F5: =B5-C5-D5-E5 -> 5978.27
A6: 5 | B6: =Revenus!E6 -> 38178 | C6: =Charges!J6 -> 59100 | D6: =Leasing!D6 -> 22099.73 | E6: =Leasing!C6 -> 0 | F6: =B6-C6-D6-E6 -> -43021.73
A7: 6 | B7: =Revenus!E7 -> 76356 | C7: =Charges!J7 -> 11500 | D7: =Leasing!D7 -> 22099.73 | E7: =Leasing!C7 -> 0 | F7: =B7-C7-D7-E7 -> 42756.27
A8: 7 | B8: =Revenus!E8 -> 76356 | C8: =Charges!J8 -> 11500 | D8: =Leasing!D8 -> 22099.73 | E8: =Leasing!C8 -> 0 | F8: =B8-C8-D8-E8 -> 42756.27
A9: 8 | B9: =Revenus!E9 -> 76356 | C9: =Charges!J9 -> 60500 | D9: =Leasing!D9 -> 22099.73 | E9: =Leasing!C9 -> 0 | F9: =B9-C9-D9-E9 -> -6243.73
A10: 9 | B10: =Revenus!E10 -> 114534 | C10: =Charges!J10 -> 12900 | D10: =Leasing!D10 -> 22099.73 | E10: =Leasing!C10 -> 0 | F10: =B10-C10-D10-E10 -> 79534.27
A11: 10 | B11: =Revenus!E11 -> 114534 | C11: =Charges!J11 -> 12900 | D11: =Leasing!D11 -> 22099.73 | E11: =Leasing!C11 -> 0 | F11: =B11-C11-D11-E11 -> 79534.27
A12: 11 | B12: =Revenus!E12 -> 114534 | C12: =Charges!J12 -> 61900 | D12: =Leasing!D12 -> 22099.73 | E12: =Leasing!C12 -> 0 | F12: =B12-C12-D12-E12 -> 30534.27
A13: 12 | B13: =Revenus!E13 -> 152712 | C13: =Charges!J13 -> 14300 | D13: =Leasing!D13 -> 22099.73 | E13: =Leasing!C13 -> 0 | F13: =B13-C13-D13-E13 -> 116312.27
... A73: 72 | B73: =Revenus!E73 -> 534492 | C73: =Charges!J73 -> 133500 | D73: =Leasing!D73 -> 465.6733 | E73: =Leasing!C73 -> 55880.796 | F73: =B73-C73-D73-E73 -> 344645.53
A74: 73 | B74: =Revenus!E74 -> 534492 | C74: =Charges!J74 -> 33500
A75: 74 | B75: =Revenus!E75 -> 534492 | C75: =Charges!J75 -> 33500
A76: 75 | B76: =Revenus!E76 -> 534492 | C76: =Charges!J76 -> 33500
A77: 76 | B77: =Revenus!E77 -> 534492 | C77: =Charges!J77 -> 33500
A78: 77 | B78: =Revenus!E78 -> 534492 | C78: =Charges!J78 -> 33500
A79: 78 | B79: =Revenus!E79 -> 534492 | C79: =Charges!J79 -> 33500
A80: 79 | B80: =Revenus!E80 -> 534492 | C80: =Charges!J80 -> 33500
A81: 80 | B81: =Revenus!E81 -> 534492 | C81: =Charges!J81 -> 33500
A82: 81 | B82: =Revenus!E82 -> 534492 | C82: =Charges!J82 -> 33500
A83: 82 | B83: =Revenus!E83 -> 534492 | C83: =Charges!J83 -> 33500
A84: 83 | B84: =Revenus!E84 -> 534492 | C84: =Charges!J84 -> 33500

Sheet Synthèse
A1: Année | B1: Revenus totaux | C1: Charges totales (incl. leasing) | D1: Résultat net annuel
A2: 1 | B2: 954450 | C2: 465596.76 | D2: 488853.24
A3: 2 | B3: 2290680 | C3: 954541.64 | D3: 1336138.4
A4: 3 | B4: 2290680 | C4: 863537.61 | D4: 1427142.4
A5: 4 | B5: 2290680 | C5: 785676.2 | D5: 1505003.8
A6: 5 | B6: 2290680 | C6: 719059.42 | D6: 1571620.6
A7: 6 | B7: 2290680 | C7: 662063.37 | D7: 1628616.6
